Workbook

Sheet Start Here
C2: Wedding Budget Planner
C3: Plan your budget, track every vendor payment, manage RSVPs and tick off your to-dos, all in one file. Works in Microsoft Excel and Google Sheets.
C5: HOW TO USE IT
B6: 1 | C6: On Dashboard, type your wedding date (and names if you like).
B7: 2 | C7: On Budget, type your total budget. Adjust the % split by category until it says 'Adds up to 100%'. Rename or add categories in the blank rows.
B8: 3 | C8: On Costs, add each vendor or purchase as you book it: committed cost, what you have paid, and when the next payment is due. Status updates by itself.
B9: 4 | C9: On Guests, add each invitation and its party size. Update RSVPs as they come in. Attending counts fill in automatically.
B10: 5 | C10: Work through Checklist and mark tasks Done. Progress shows on the Dashboard.
B11: 6 | C11: Dashboard shows days to go, money committed and paid, overdue payments, cost per guest and RSVPs.
C13: CELL COLOURS
C14: Cream cells are for typing. Everything else calculates on its own.
C16: GOOD TO KNOW
C17: Google Sheets: upload the file to Google Drive, then open it with Google Sheets.
C18: Dollar signs are only formatting. To change currency, select the cells and use Format > Number.
C19: Room for 20 budget categories, 150 costs and 300 invitations.
C20: The starting % split is a suggestion, not a rule. Every wedding is different.
C21: Please do not type over the white formula cells. If something breaks, re-download the original from Etsy (Purchases > Download files).

Sheet Dashboard
B2: Our Wedding Dashboard
B5: Wedding date | G5: Names (optional)
B7: DAYS TO GO | D7: TOTAL BUDGET | G7: COMMITTED SO FAR | J7: LEFT TO COMMIT
B8: =IF(D5="","Add date",MAX(0,D5-TODAY())) | D8: =Budget!C5 | G8: =Budget!E28 | J8: =Budget!C5-Budget!E28
B10: PAID SO FAR | D10: STILL TO PAY | G10: PAYMENTS OVERDUE | J10: COST PER GUEST
B11: =Budget!F28 | D11: =Budget!G28 | G11: =COUNTIF(Costs!J7:J156,"Overdue") | J11: =IF(N(E15)=0,"-",Budget!E28/E15)
B13: GUESTS (PEOPLE, NOT INVITATIONS)
B14: INVITED | E14: ATTENDING | H14: DECLINED | K14: STILL WAITING
B15: =SUM(Guests!D7:D306) | E15: =SUM(Guests!I7:I306) | H15: =SUMIFS(Guests!D7:D306,Guests!H7:H306,"No") | K15: =B15-E15-H15
B17: CHECKLIST
B18: Tasks done | D18: =Checklist!C5

Sheet Budget
B2: Budget plan
B3: Set your total, split it by category, and watch real costs against the plan.
B5: Total budget | C5: 0 | E5: Split used | F5: =SUM(C8:C27) | G5: =IF(ROUND(F5,4)=1,"Adds up to 100%",IF(F5<1,"Under 100%: "&TEXT(1-F5,"0%")&" unassigned","Over 100% by "&TEXT(F5-1,"0%")))
B7: Category | C7: % of budget | D7: Planned | E7: Committed cost | F7: Paid so far | G7: Still to pay | H7: Left in plan
B8: Venue & rentals | C8: 0.28 | D8: =IF(B8="","",$C$5*C8) | E8: =IF(B8="","",SUMIFS(Costs!$F$7:$F$156,Costs!$B$7:$B$156,$B8)) | F8: =IF(B8="","",SUMIFS(Costs!$G$7:$G$156,Costs!$B$7:$B$156,$B8)) | G8: =IF(B8="","",E8-F8) | H8: =IF(B8="","",D8-E8)
B9: Catering & bar | C9: 0.22 | D9: =IF(B9="","",$C$5*C9) | E9: =IF(B9="","",SUMIFS(Costs!$F$7:$F$156,Costs!$B$7:$B$156,$B9)) | F9: =IF(B9="","",SUMIFS(Costs!$G$7:$G$156,Costs!$B$7:$B$156,$B9)) | G9: =IF(B9="","",E9-F9) | H9: =IF(B9="","",D9-E9)
B10: Photography & video | C10: 0.12 | D10: =IF(B10="","",$C$5*C10) | E10: =IF(B10="","",SUMIFS(Costs!$F$7:$F$156,Costs!$B$7:$B$156,$B10)) | F10: =IF(B10="","",SUMIFS(Costs!$G$7:$G$156,Costs!$B$7:$B$156,$B10)) | G10: =IF(B10="","",E10-F10) | H10: =IF(B10="","",D10-E10)
B11: Attire & beauty | C11: 0.08 | D11: =IF(B11="","",$C$5*C11) | E11: =IF(B11="","",SUMIFS(Costs!$F$7:$F$156,Costs!$B$7:$B$156,$B11)) | F11: =IF(B11="","",SUMIFS(Costs!$G$7:$G$156,Costs!$B$7:$B$156,$B11)) | G11: =IF(B11="","",E11-F11) | H11: =IF(B11="","",D11-E11)
B12: Flowers & decor | C12: 0.08 | D12: =IF(B12="","",$C$5*C12) | E12: =IF(B12="","",SUMIFS(Costs!$F$7:$F$156,Costs!$B$7:$B$156,$B12)) | F12: =IF(B12="","",SUMIFS(Costs!$G$7:$G$156,Costs!$B$7:$B$156,$B12)) | G12: =IF(B12="","",E12-F12) | H12: =IF(B12="","",D12-E12)
B13: Music & entertainment | C13: 0.06 | D13: =IF(B13="","",$C$5*C13) | E13: =IF(B13="","",SUMIFS(Costs!$F$7:$F$156,Costs!$B$7:$B$156,$B13)) | F13: =IF(B13="","",SUMIFS(Costs!$G$7:$G$156,Costs!$B$7:$B$156,$B13)) | G13: =IF(B13="","",E13-F13) | H13: =IF(B13="","",D13-E13)
B14: Planner / coordinator | C14: 0.03 | D14: =IF(B14="","",$C$5*C14) | E14: =IF(B14="","",SUMIFS(Costs!$F$7:$F$156,Costs!$B$7:$B$156,$B14)) | F14: =IF(B14="","",SUMIFS(Costs!$G$7:$G$156,Costs!$B$7:$B$156,$B14)) | G14: =IF(B14="","",E14-F14) | H14: =IF(B14="","",D14-E14)
B15: Rings | C15: 0.03 | D15: =IF(B15="","",$C$5*C15) | E15: =IF(B15="","",SUMIFS(Costs!$F$7:$F$156,Costs!$B$7:$B$156,$B15)) | F15: =IF(B15="","",SUMIFS(Costs!$G$7:$G$156,Costs!$B$7:$B$156,$B15)) | G15: =IF(B15="","",E15-F15) | H15: =IF(B15="","",D15-E15)
B16: Cake & desserts | C16: 0.02 | D16: =IF(B16="","",$C$5*C16) | E16: =IF(B16="","",SUMIFS(Costs!$F$7:$F$156,Costs!$B$7:$B$156,$B16)) | F16: =IF(B16="","",SUMIFS(Costs!$G$7:$G$156,Costs!$B$7:$B$156,$B16)) | G16: =IF(B16="","",E16-F16) | H16: =IF(B16="","",D16-E16)
B17: Stationery & postage | C17: 0.02 | D17: =IF(B17="","",$C$5*C17) | E17: =IF(B17="","",SUMIFS(Costs!$F$7:$F$156,Costs!$B$7:$B$156,$B17)) | F17: =IF(B17="","",SUMIFS(Costs!$G$7:$G$156,Costs!$B$7:$B$156,$B17)) | G17: =IF(B17="","",E17-F17) | H17: =IF(B17="","",D17-E17)
B18: Transportation | C18: 0.02 | D18: =IF(B18="","",$C$5*C18) | E18: =IF(B18="","",SUMIFS(Costs!$F$7:$F$156,Costs!$B$7:$B$156,$B18)) | F18: =IF(B18="","",SUMIFS(Costs!$G$7:$G$156,Costs!$B$7:$B$156,$B18)) | G18: =IF(B18="","",E18-F18) | H18: =IF(B18="","",D18-E18)
B19: Favors & gifts | C19: 0.02 | D19: =IF(B19="","",$C$5*C19) | E19: =IF(B19="","",SUMIFS(Costs!$F$7:$F$156,Costs!$B$7:$B$156,$B19)) | F19: =IF(B19="","",SUMIFS(Costs!$G$7:$G$156,Costs!$B$7:$B$156,$B19)) | G19: =IF(B19="","",E19-F19) | H19: =IF(B19="","",D19-E19)
... B21: Buffer for surprises | C21: 0.01 | D21: =IF(B21="","",$C$5*C21) | E21: =IF(B21="","",SUMIFS(Costs!$F$7:$F$156,Costs!$B$7:$B$156,$B21)) | F21: =IF(B21="","",SUMIFS(Costs!$G$7:$G$156,Costs!$B$7:$B$156,$B21)) | G21: =IF(B21="","",E21-F21) | H21: =IF(B21="","",D21-E21)
D22: =IF(B22="","",$C$5*C22) | E22: =IF(B22="","",SUMIFS(Costs!$F$7:$F$156,Costs!$B$7:$B$156,$B22)) | F22: =IF(B22="","",SUMIFS(Costs!$G$7:$G$156,Costs!$B$7:$B$156,$B22)) | G22: =IF(B22="","",E22-F22) | H22: =IF(B22="","",D22-E22)
D23: =IF(B23="","",$C$5*C23) | E23: =IF(B23="","",SUMIFS(Costs!$F$7:$F$156,Costs!$B$7:$B$156,$B23)) | F23: =IF(B23="","",SUMIFS(Costs!$G$7:$G$156,Costs!$B$7:$B$156,$B23)) | G23: =IF(B23="","",E23-F23) | H23: =IF(B23="","",D23-E23)
D24: =IF(B24="","",$C$5*C24) | E24: =IF(B24="","",SUMIFS(Costs!$F$7:$F$156,Costs!$B$7:$B$156,$B24)) | F24: =IF(B24="","",SUMIFS(Costs!$G$7:$G$156,Costs!$B$7:$B$156,$B24)) | G24: =IF(B24="","",E24-F24) | H24: =IF(B24="","",D24-E24)
D25: =IF(B25="","",$C$5*C25) | E25: =IF(B25="","",SUMIFS(Costs!$F$7:$F$156,Costs!$B$7:$B$156,$B25)) | F25: =IF(B25="","",SUMIFS(Costs!$G$7:$G$156,Costs!$B$7:$B$156,$B25)) | G25: =IF(B25="","",E25-F25) | H25: =IF(B25="","",D25-E25)
D26: =IF(B26="","",$C$5*C26) | E26: =IF(B26="","",SUMIFS(Costs!$F$7:$F$156,Costs!$B$7:$B$156,$B26)) | F26: =IF(B26="","",SUMIFS(Costs!$G$7:$G$156,Costs!$B$7:$B$156,$B26)) | G26: =IF(B26="","",E26-F26) | H26: =IF(B26="","",D26-E26)
D27: =IF(B27="","",$C$5*C27) | E27: =IF(B27="","",SUMIFS(Costs!$F$7:$F$156,Costs!$B$7:$B$156,$B27)) | F27: =IF(B27="","",SUMIFS(Costs!$G$7:$G$156,Costs!$B$7:$B$156,$B27)) | G27: =IF(B27="","",E27-F27) | H27: =IF(B27="","",D27-E27)
B28: Totals | D28: =SUM(D8:D27) | E28: =SUM(E8:E27) | F28: =SUM(F8:F27) | G28: =SUM(G8:G27) | H28: =SUM(H8:H27)
B30: The starting split is only a suggestion to get you going. Change the % to match what matters to you. Red = over plan.

Sheet Costs
B2: Costs & payments
B3: One row per vendor or purchase. Deposits and balances in one place.
B6: Category | C6: Item | D6: Vendor | E6: Contact | F6: Committed cost | G6: Paid so far | H6: Still to pay | I6: Next payment due | J6: Status | K6: Notes
H7: =IF(F7="","",F7-N(G7)) | J7: =IF(F7="","",IF(H7<=0,"Paid in full",IF(I7="","Balance due",IF(I7<TODAY(),"Overdue",IF(I7-TODAY()<=30,"Due within 30 days","Scheduled")))))
H8: =IF(F8="","",F8-N(G8)) | J8: =IF(F8="","",IF(H8<=0,"Paid in full",IF(I8="","Balance due",IF(I8<TODAY(),"Overdue",IF(I8-TODAY()<=30,"Due within 30 days","Scheduled")))))
H9: =IF(F9="","",F9-N(G9)) | J9: =IF(F9="","",IF(H9<=0,"Paid in full",IF(I9="","Balance due",IF(I9<TODAY(),"Overdue",IF(I9-TODAY()<=30,"Due within 30 days","Scheduled")))))
H10: =IF(F10="","",F10-N(G10)) | J10: =IF(F10="","",IF(H10<=0,"Paid in full",IF(I10="","Balance due",IF(I10<TODAY(),"Overdue",IF(I10-TODAY()<=30,"Due within 30 days","Scheduled")))))
H11: =IF(F11="","",F11-N(G11)) | J11: =IF(F11="","",IF(H11<=0,"Paid in full",IF(I11="","Balance due",IF(I11<TODAY(),"Overdue",IF(I11-TODAY()<=30,"Due within 30 days","Scheduled")))))
H12: =IF(F12="","",F12-N(G12)) | J12: =IF(F12="","",IF(H12<=0,"Paid in full",IF(I12="","Balance due",IF(I12<TODAY(),"Overdue",IF(I12-TODAY()<=30,"Due within 30 days","Scheduled")))))
H13: =IF(F13="","",F13-N(G13)) | J13: =IF(F13="","",IF(H13<=0,"Paid in full",IF(I13="","Balance due",IF(I13<TODAY(),"Overdue",IF(I13-TODAY()<=30,"Due within 30 days","Scheduled")))))
H14: =IF(F14="","",F14-N(G14)) | J14: =IF(F14="","",IF(H14<=0,"Paid in full",IF(I14="","Balance due",IF(I14<TODAY(),"Overdue",IF(I14-TODAY()<=30,"Due within 30 days","Scheduled")))))
H15: =IF(F15="","",F15-N(G15)) | J15: =IF(F15="","",IF(H15<=0,"Paid in full",IF(I15="","Balance due",IF(I15<TODAY(),"Overdue",IF(I15-TODAY()<=30,"Due within 30 days","Scheduled")))))
H16: =IF(F16="","",F16-N(G16)) | J16: =IF(F16="","",IF(H16<=0,"Paid in full",IF(I16="","Balance due",IF(I16<TODAY(),"Overdue",IF(I16-TODAY()<=30,"Due within 30 days","Scheduled")))))
H17: =IF(F17="","",F17-N(G17)) | J17: =IF(F17="","",IF(H17<=0,"Paid in full",IF(I17="","Balance due",IF(I17<TODAY(),"Overdue",IF(I17-TODAY()<=30,"Due within 30 days","Scheduled")))))
H18: =IF(F18="","",F18-N(G18)) | J18: =IF(F18="","",IF(H18<=0,"Paid in full",IF(I18="","Balance due",IF(I18<TODAY(),"Overdue",IF(I18-TODAY()<=30,"Due within 30 days","Scheduled")))))
... H156: =IF(F156="","",F156-N(G156)) | J156: =IF(F156="","",IF(H156<=0,"Paid in full",IF(I156="","Balance due",IF(I156<TODAY(),"Overdue",IF(I156-TODAY()<=30,"Due within 30 days","Scheduled")))))

Sheet Guests
B2: Guest list & RSVPs
B3: One row per invitation. Put the number of people it covers in Party size.
B6: Name(s) | C6: Side | D6: Party size | E6: Email / phone | F6: Save-the-date | G6: Invite sent | H6: RSVP | I6: Attending | J6: Meal choice | K6: Dietary needs | L6: Table | M6: Gift | N6: Thank-you sent
I7: =IF(H7="Yes",N(D7),IF(B7="","",0))
I8: =IF(H8="Yes",N(D8),IF(B8="","",0))
I9: =IF(H9="Yes",N(D9),IF(B9="","",0))
I10: =IF(H10="Yes",N(D10),IF(B10="","",0))
I11: =IF(H11="Yes",N(D11),IF(B11="","",0))
I12: =IF(H12="Yes",N(D12),IF(B12="","",0))
I13: =IF(H13="Yes",N(D13),IF(B13="","",0))
I14: =IF(H14="Yes",N(D14),IF(B14="","",0))
I15: =IF(H15="Yes",N(D15),IF(B15="","",0))
I16: =IF(H16="Yes",N(D16),IF(B16="","",0))
I17: =IF(H17="Yes",N(D17),IF(B17="","",0))
I18: =IF(H18="Yes",N(D18),IF(B18="","",0))
... I306: =IF(H306="Yes",N(D306),IF(B306="","",0))

Sheet Checklist
B2: Planning checklist
B3: A timeline to work from. Mark tasks Done, add your own in the blank rows.
B5: Progress | C5: =IFERROR(COUNTIF(D7:D59,"Done")/(COUNTA(C7:C59)-COUNTIF(D7:D59,"Skip")),0)
B6: When | C6: Task | D6: Done? | E6: Deadline | F6: Notes
B7: 12+ months | C7: Set your total budget and decide who is paying for what
B8: 12+ months | C8: Draft a rough guest list and head count
B9: 12+ months | C9: Pick a season or date range
B10: 12+ months | C10: Book the venue
B11: 12+ months | C11: Decide if you want a planner or coordinator
B12: 12+ months
B13: 9-12 months | C13: Book photographer and videographer
B14: 9-12 months | C14: Book caterer (if not with venue)
B15: 9-12 months | C15: Book officiant
B16: 9-12 months | C16: Start looking at attire
B17: 9-12 months | C17: Set up a wedding website (optional)
B18: 9-12 months | C18: Reserve hotel blocks for guests
B19: 9-12 months
B20: 6-9 months | C20: Book music / DJ / band
B21: 6-9 months | C21: Book florist
B22: 6-9 months | C22: Send save-the-dates
B23: 6-9 months | C23: Order attire
B24: 6-9 months | C24: Plan the honeymoon
B25: 6-9 months | C25: Register for gifts
B26: 6-9 months
B27: 4-6 months | C27: Book hair and makeup
B28: 4-6 months | C28: Order invitations
B29: 4-6 months | C29: Book transportation
B30: 4-6 months | C30: Order cake / desserts
B31: 4-6 months | C31: Buy rings
B32: 4-6 months | C32: Plan rehearsal dinner
B33: 4-6 months
B34: 2-3 months | C34: Mail invitations
B35: 2-3 months | C35: First attire fitting
B36: 2-3 months | C36: Finalize menu and bar
B37: 2-3 months | C37: Write or plan vows
B38: 2-3 months | C38: Buy gifts for the wedding party
B39: 2-3 months | C39: Check marriage license requirements
B40: 2-3 months
B41: 1 month | C41: Chase missing RSVPs
B42: 1 month | C42: Give final numbers to caterer and venue
...
