Workbook

Sheet Start Here
C2: Debt Payoff Planner
C3: See exactly when you will be debt-free, and compare the snowball and avalanche methods side by side. Works in Microsoft Excel and Google Sheets.
C5: HOW TO USE IT
B6: 1 | C6: Go to My Debts. Type each debt's name, balance, APR and minimum payment (up to 10 debts).
B7: 2 | C7: Enter the first month of your plan and any extra amount you can pay each month on top of the minimums.
B8: 3 | C8: Open Compare to see your debt-free date, total interest and payoff order for each method.
B9: 4 | C9: Pick Snowball or Avalanche on My Debts. Pay your monthly debt budget every month, following the payoff order.
B10: 5 | C10: Each month, log what you really owe on Progress Log.
B11: 6 | C11: Want the detail? The Snowball, Avalanche and Minimum Only tabs show every month for up to 25 years.
C13: CELL COLOURS
C14: Cream cells are for typing. Everything else calculates on its own.
C16: GOOD TO KNOW
C17: Google Sheets: File > Import > Upload, or upload to Google Drive and open with Google Sheets.
C18: Type APR as a plain number, e.g. 22.99 for 22.99%.
C19: Interest is estimated monthly (balance x APR / 12). Your lender may calculate it daily, so their numbers will be a little different.
C20: This is a planning tool, not financial advice. Check payoff amounts with your lender.
C21: Please do not change the white formula cells. If something breaks, re-download your original file from Etsy (Purchases > Download files).

Sheet My Debts
B2: My Debts
B3: List every debt once. Everything else in this file updates from this page.
B5: YOUR PLAN SETTINGS
B6: First month of your plan | C6: 46296 | D6: Pick the 1st of the month you start.
B7: Extra you can pay each month | C7: 0 | D7: On top of your minimum payments. Can be $0.
B8: Method you will follow | C8: Snowball | D8: Not sure? See the Compare tab.
B9: Debt name | C9: Balance now | D9: APR (%) | E9: Minimum payment | F9: Snowball order | G9: Avalanche order
F10: =IF(OR(B10="",N(C10)<=0),"",J10) | G10: =IF(OR(B10="",N(C10)<=0),"",K10) | H10: =IF(OR(B10="",N(C10)<=0),1E9+ROW(),C10+ROW()/1E6) | I10: =IF(OR(B10="",N(C10)<=0),1E9+ROW(),-N(D10)+ROW()/1E6) | J10: =RANK(H10,$H$10:$H$19,1) | K10: =RANK(I10,$I$10:$I$19,1)
F11: =IF(OR(B11="",N(C11)<=0),"",J11) | G11: =IF(OR(B11="",N(C11)<=0),"",K11) | H11: =IF(OR(B11="",N(C11)<=0),1E9+ROW(),C11+ROW()/1E6) | I11: =IF(OR(B11="",N(C11)<=0),1E9+ROW(),-N(D11)+ROW()/1E6) | J11: =RANK(H11,$H$10:$H$19,1) | K11: =RANK(I11,$I$10:$I$19,1)
F12: =IF(OR(B12="",N(C12)<=0),"",J12) | G12: =IF(OR(B12="",N(C12)<=0),"",K12) | H12: =IF(OR(B12="",N(C12)<=0),1E9+ROW(),C12+ROW()/1E6) | I12: =IF(OR(B12="",N(C12)<=0),1E9+ROW(),-N(D12)+ROW()/1E6) | J12: =RANK(H12,$H$10:$H$19,1) | K12: =RANK(I12,$I$10:$I$19,1)
F13: =IF(OR(B13="",N(C13)<=0),"",J13) | G13: =IF(OR(B13="",N(C13)<=0),"",K13) | H13: =IF(OR(B13="",N(C13)<=0),1E9+ROW(),C13+ROW()/1E6) | I13: =IF(OR(B13="",N(C13)<=0),1E9+ROW(),-N(D13)+ROW()/1E6) | J13: =RANK(H13,$H$10:$H$19,1) | K13: =RANK(I13,$I$10:$I$19,1)
F14: =IF(OR(B14="",N(C14)<=0),"",J14) | G14: =IF(OR(B14="",N(C14)<=0),"",K14) | H14: =IF(OR(B14="",N(C14)<=0),1E9+ROW(),C14+ROW()/1E6) | I14: =IF(OR(B14="",N(C14)<=0),1E9+ROW(),-N(D14)+ROW()/1E6) | J14: =RANK(H14,$H$10:$H$19,1) | K14: =RANK(I14,$I$10:$I$19,1)
F15: =IF(OR(B15="",N(C15)<=0),"",J15) | G15: =IF(OR(B15="",N(C15)<=0),"",K15) | H15: =IF(OR(B15="",N(C15)<=0),1E9+ROW(),C15+ROW()/1E6) | I15: =IF(OR(B15="",N(C15)<=0),1E9+ROW(),-N(D15)+ROW()/1E6) | J15: =RANK(H15,$H$10:$H$19,1) | K15: =RANK(I15,$I$10:$I$19,1)
F16: =IF(OR(B16="",N(C16)<=0),"",J16) | G16: =IF(OR(B16="",N(C16)<=0),"",K16) | H16: =IF(OR(B16="",N(C16)<=0),1E9+ROW(),C16+ROW()/1E6) | I16: =IF(OR(B16="",N(C16)<=0),1E9+ROW(),-N(D16)+ROW()/1E6) | J16: =RANK(H16,$H$10:$H$19,1) | K16: =RANK(I16,$I$10:$I$19,1)
F17: =IF(OR(B17="",N(C17)<=0),"",J17) | G17: =IF(OR(B17="",N(C17)<=0),"",K17) | H17: =IF(OR(B17="",N(C17)<=0),1E9+ROW(),C17+ROW()/1E6) | I17: =IF(OR(B17="",N(C17)<=0),1E9+ROW(),-N(D17)+ROW()/1E6) | J17: =RANK(H17,$H$10:$H$19,1) | K17: =RANK(I17,$I$10:$I$19,1)
F18: =IF(OR(B18="",N(C18)<=0),"",J18) | G18: =IF(OR(B18="",N(C18)<=0),"",K18) | H18: =IF(OR(B18="",N(C18)<=0),1E9+ROW(),C18+ROW()/1E6) | I18: =IF(OR(B18="",N(C18)<=0),1E9+ROW(),-N(D18)+ROW()/1E6) | J18: =RANK(H18,$H$10:$H$19,1) | K18: =RANK(I18,$I$10:$I$19,1)
F19: =IF(OR(B19="",N(C19)<=0),"",J19) | G19: =IF(OR(B19="",N(C19)<=0),"",K19) | H19: =IF(OR(B19="",N(C19)<=0),1E9+ROW(),C19+ROW()/1E6) | I19: =IF(OR(B19="",N(C19)<=0),1E9+ROW(),-N(D19)+ROW()/1E6) | J19: =RANK(H19,$H$10:$H$19,1) | K19: =RANK(I19,$I$10:$I$19,1)
B20: Totals | C20: =SUM(C10:C19) | E20: =SUM(E10:E19)
B21: Monthly debt budget | E21: =E20+C7 | F21: Minimums + extra, every month.
B23: YOUR PLAN AT A GLANCE
B24: DEBT-FREE BY | C24: MONTHS TO GO | E24: TOTAL INTEREST | F24: INTEREST SAVED
B25: =IF($C$8="Avalanche",Compare!C7,Compare!C6) | C25: =IF($C$8="Avalanche",Compare!D7,Compare!D6) | E25: =IF($C$8="Avalanche",Compare!E7,Compare!E6) | F25: =IF($C$8="Avalanche",Compare!G7,Compare!G6)
B27: Interest saved is compared with paying only the minimums. Estimates only: interest is worked out monthly as balance x APR / 12.

Sheet Compare
B2: Compare methods
B3: Same monthly budget, three ways to use it. Pick yours on the My Debts tab.
B5: Method | C5: Debt-free by | D5: Months | E5: Total interest | F5: Total paid | G5: Interest saved vs minimums
B6: Snowball | C6: =IF(ISNUMBER(D6),EDATE('My Debts'!$C$6,MAX(D6,1)-1),"Not in 25 yrs") | D6: =IF('My Debts'!$C$20<=0,0,IF(COUNTIF('Snowball'!$C$8:$C$307,">0.005")>=300,"25+ yrs",COUNTIF('Snowball'!$C$8:$C$307,">0.005")+1)) | E6: =SUM('Snowball'!$E$8:$E$307) | F6: =SUM('Snowball'!$D$8:$D$307) | G6: =E8-E6
B7: Avalanche | C7: =IF(ISNUMBER(D7),EDATE('My Debts'!$C$6,MAX(D7,1)-1),"Not in 25 yrs") | D7: =IF('My Debts'!$C$20<=0,0,IF(COUNTIF('Avalanche'!$C$8:$C$307,">0.005")>=300,"25+ yrs",COUNTIF('Avalanche'!$C$8:$C$307,">0.005")+1)) | E7: =SUM('Avalanche'!$E$8:$E$307) | F7: =SUM('Avalanche'!$D$8:$D$307) | G7: =E8-E7
B8: Minimums only | C8: =IF(ISNUMBER(D8),EDATE('My Debts'!$C$6,MAX(D8,1)-1),"Not in 25 yrs") | D8: =IF('My Debts'!$C$20<=0,0,IF(COUNTIF('Minimum Only'!$C$8:$C$307,">0.005")>=300,"25+ yrs",COUNTIF('Minimum Only'!$C$8:$C$307,">0.005")+1)) | E8: =SUM('Minimum Only'!$E$8:$E$307) | F8: =SUM('Minimum Only'!$D$8:$D$307) | G8: —
B10: If minimums never clear a debt within 25 years, the minimum-only interest shown is only the first 25 years, so real savings are larger.
B11: Snowball often feels better (quick wins). Avalanche usually costs less. The best plan is the one you stick with.
B13: SNOWBALL ORDER | I13: AVALANCHE ORDER
B14: Debt | C14: Paid off | D14: Interest paid | I14: # | J14: Debt | K14: Paid off | L14: Interest paid
B15: ='Snowball'!K6 | C15: =IF('Snowball'!K6="","",IF(COUNTIF('Snowball'!$K$8:$K$307,">0.005")>=300,"Not in 25 yrs",EDATE('My Debts'!$C$6,COUNTIF('Snowball'!$K$8:$K$307,">0.005")))) | D15: =IF('Snowball'!K6="","",SUM('Snowball'!$H$8:$H$307)) | I15: 1 | J15: ='Avalanche'!K6 | K15: =IF('Avalanche'!K6="","",IF(COUNTIF('Avalanche'!$K$8:$K$307,">0.005")>=300,"Not in 25 yrs",EDATE('My Debts'!$C$6,COUNTIF('Avalanche'!$K$8:$K$307,">0.005")))) | L15: =IF('Avalanche'!K6="","",SUM('Avalanche'!$H$8:$H$307))
B16: ='Snowball'!Q6 | C16: =IF('Snowball'!Q6="","",IF(COUNTIF('Snowball'!$Q$8:$Q$307,">0.005")>=300,"Not in 25 yrs",EDATE('My Debts'!$C$6,COUNTIF('Snowball'!$Q$8:$Q$307,">0.005")))) | D16: =IF('Snowball'!Q6="","",SUM('Snowball'!$N$8:$N$307)) | I16: 2 | J16: ='Avalanche'!Q6 | K16: =IF('Avalanche'!Q6="","",IF(COUNTIF('Avalanche'!$Q$8:$Q$307,">0.005")>=300,"Not in 25 yrs",EDATE('My Debts'!$C$6,COUNTIF('Avalanche'!$Q$8:$Q$307,">0.005")))) | L16: =IF('Avalanche'!Q6="","",SUM('Avalanche'!$N$8:$N$307))
B17: ='Snowball'!W6 | C17: =IF('Snowball'!W6="","",IF(COUNTIF('Snowball'!$W$8:$W$307,">0.005")>=300,"Not in 25 yrs",EDATE('My Debts'!$C$6,COUNTIF('Snowball'!$W$8:$W$307,">0.005")))) | D17: =IF('Snowball'!W6="","",SUM('Snowball'!$T$8:$T$307)) | I17: 3 | J17: ='Avalanche'!W6 | K17: =IF('Avalanche'!W6="","",IF(COUNTIF('Avalanche'!$W$8:$W$307,">0.005")>=300,"Not in 25 yrs",EDATE('My Debts'!$C$6,COUNTIF('Avalanche'!$W$8:$W$307,">0.005")))) | L17: =IF('Avalanche'!W6="","",SUM('Avalanche'!$T$8:$T$307))
B18: ='Snowball'!AC6 | C18: =IF('Snowball'!AC6="","",IF(COUNTIF('Snowball'!$AC$8:$AC$307,">0.005")>=300,"Not in 25 yrs",EDATE('My Debts'!$C$6,COUNTIF('Snowball'!$AC$8:$AC$307,">0.005")))) | D18: =IF('Snowball'!AC6="","",SUM('Snowball'!$Z$8:$Z$307)) | I18: 4 | J18: ='Avalanche'!AC6 | K18: =IF('Avalanche'!AC6="","",IF(COUNTIF('Avalanche'!$AC$8:$AC$307,">0.005")>=300,"Not in 25 yrs",EDATE('My Debts'!$C$6,COUNTIF('Avalanche'!$AC$8:$AC$307,">0.005")))) | L18: =IF('Avalanche'!AC6="","",SUM('Avalanche'!$Z$8:$Z$307))
B19: ='Snowball'!AI6 | C19: =IF('Snowball'!AI6="","",IF(COUNTIF('Snowball'!$AI$8:$AI$307,">0.005")>=300,"Not in 25 yrs",EDATE('My Debts'!$C$6,COUNTIF('Snowball'!$AI$8:$AI$307,">0.005")))) | D19: =IF('Snowball'!AI6="","",SUM('Snowball'!$AF$8:$AF$307)) | I19: 5 | J19: ='Avalanche'!AI6 | K19: =IF('Avalanche'!AI6="","",IF(COUNTIF('Avalanche'!$AI$8:$AI$307,">0.005")>=300,"Not in 25 yrs",EDATE('My Debts'!$C$6,COUNTIF('Avalanche'!$AI$8:$AI$307,">0.005")))) | L19: =IF('Avalanche'!AI6="","",SUM('Avalanche'!$AF$8:$AF$307))
B20: ='Snowball'!AO6 | C20: =IF('Snowball'!AO6="","",IF(COUNTIF('Snowball'!$AO$8:$AO$307,">0.005")>=300,"Not in 25 yrs",EDATE('My Debts'!$C$6,COUNTIF('Snowball'!$AO$8:$AO$307,">0.005")))) | D20: =IF('Snowball'!AO6="","",SUM('Snowball'!$AL$8:$AL$307)) | I20: 6 | J20: ='Avalanche'!AO6 | K20: =IF('Avalanche'!AO6="","",IF(COUNTIF('Avalanche'!$AO$8:$AO$307,">0.005")>=300,"Not in 25 yrs",EDATE('My Debts'!$C$6,COUNTIF('Avalanche'!$AO$8:$AO$307,">0.005")))) | L20: =IF('Avalanche'!AO6="","",SUM('Avalanche'!$AL$8:$AL$307))
B21: ='Snowball'!AU6 | C21: =IF('Snowball'!AU6="","",IF(COUNTIF('Snowball'!$AU$8:$AU$307,">0.005")>=300,"Not in 25 yrs",EDATE('My Debts'!$C$6,COUNTIF('Snowball'!$AU$8:$AU$307,">0.005")))) | D21: =IF('Snowball'!AU6="","",SUM('Snowball'!$AR$8:$AR$307)) | I21: 7 | J21: ='Avalanche'!AU6 | K21: =IF('Avalanche'!AU6="","",IF(COUNTIF('Avalanche'!$AU$8:$AU$307,">0.005")>=300,"Not in 25 yrs",EDATE('My Debts'!$C$6,COUNTIF('Avalanche'!$AU$8:$AU$307,">0.005")))) | L21: =IF('Avalanche'!AU6="","",SUM('Avalanche'!$AR$8:$AR$307))
B22: ='Snowball'!BA6 | C22: =IF('Snowball'!BA6="","",IF(COUNTIF('Snowball'!$BA$8:$BA$307,">0.005")>=300,"Not in 25 yrs",EDATE('My Debts'!$C$6,COUNTIF('Snowball'!$BA$8:$BA$307,">0.005")))) | D22: =IF('Snowball'!BA6="","",SUM('Snowball'!$AX$8:$AX$307)) | I22: 8 | J22: ='Avalanche'!BA6 | K22: =IF('Avalanche'!BA6="","",IF(COUNTIF('Avalanche'!$BA$8:$BA$307,">0.005")>=300,"Not in 25 yrs",EDATE('My Debts'!$C$6,COUNTIF('Avalanche'!$BA$8:$BA$307,">0.005")))) | L22: =IF('Avalanche'!BA6="","",SUM('Avalanche'!$AX$8:$AX$307))
B23: ='Snowball'!BG6 | C23: =IF('Snowball'!BG6="","",IF(COUNTIF('Snowball'!$BG$8:$BG$307,">0.005")>=300,"Not in 25 yrs",EDATE('My Debts'!$C$6,COUNTIF('Snowball'!$BG$8:$BG$307,">0.005")))) | D23: =IF('Snowball'!BG6="","",SUM('Snowball'!$BD$8:$BD$307)) | I23: 9 | J23: ='Avalanche'!BG6 | K23: =IF('Avalanche'!BG6="","",IF(COUNTIF('Avalanche'!$BG$8:$BG$307,">0.005")>=300,"Not in 25 yrs",EDATE('My Debts'!$C$6,COUNTIF('Avalanche'!$BG$8:$BG$307,">0.005")))) | L23: =IF('Avalanche'!BG6="","",SUM('Avalanche'!$BD$8:$BD$307))
B24: ='Snowball'!BM6 | C24: =IF('Snowball'!BM6="","",IF(COUNTIF('Snowball'!$BM$8:$BM$307,">0.005")>=300,"Not in 25 yrs",EDATE('My Debts'!$C$6,COUNTIF('Snowball'!$BM$8:$BM$307,">0.005")))) | D24: =IF('Snowball'!BM6="","",SUM('Snowball'!$BJ$8:$BJ$307)) | I24: 10 | J24: ='Avalanche'!BM6 | K24: =IF('Avalanche'!BM6="","",IF(COUNTIF('Avalanche'!$BM$8:$BM$307,">0.005")>=300,"Not in 25 yrs",EDATE('My Debts'!$C$6,COUNTIF('Avalanche'!$BM$8:$BM$307,">0.005")))) | L24: =IF('Avalanche'!BM6="","",SUM('Avalanche'!$BJ$8:$BJ$307))
B26: Chart shows the first 15 years.

Sheet Snowball
B2: Snowball schedule
B3: Smallest balance first. Each paid-off debt's payment rolls into the next one.
G5: ="Payoff #1: "&IF(K6="","(empty)",K6) | M5: ="Payoff #2: "&IF(Q6="","(empty)",Q6) | S5: ="Payoff #3: "&IF(W6="","(empty)",W6) | Y5: ="Payoff #4: "&IF(AC6="","(empty)",AC6) | AE5: ="Payoff #5: "&IF(AI6="","(empty)",AI6) | AK5: ="Payoff #6: "&IF(AO6="","(empty)",AO6) | AQ5: ="Payoff #7: "&IF(AU6="","(empty)",AU6) | AW5: ="Payoff #8: "&IF(BA6="","(empty)",BA6) | BC5: ="Payoff #9: "&IF(BG6="","(empty)",BG6) | BI5: ="Payoff #10: "&IF(BM6="","(empty)",BM6)
G6: =MATCH(1,'My Debts'!$J$10:$J$19,0) | H6: =N(INDEX('My Debts'!$D$10:$D$19,G$6))/100 | I6: =IF(INDEX('My Debts'!$B$10:$B$19,G$6)="",0,N(INDEX('My Debts'!$E$10:$E$19,G$6))) | J6: =IF(INDEX('My Debts'!$B$10:$B$19,G$6)="",0,N(INDEX('My Debts'!$C$10:$C$19,G$6))) | K6: =IF(INDEX('My Debts'!$B$10:$B$19,G$6)="","",INDEX('My Debts'!$B$10:$B$19,G$6)) | M6: =MATCH(2,'My Debts'!$J$10:$J$19,0) | N6: =N(INDEX('My Debts'!$D$10:$D$19,M$6))/100 | O6: =IF(INDEX('My Debts'!$B$10:$B$19,M$6)="",0,N(INDEX('My Debts'!$E$10:$E$19,M$6))) | P6: =IF(INDEX('My Debts'!$B$10:$B$19,M$6)="",0,N(INDEX('My Debts'!$C$10:$C$19,M$6))) | Q6: =IF(INDEX('My Debts'!$B$10:$B$19,M$6)="","",INDEX('My Debts'!$B$10:$B$19,M$6)) | S6: =MATCH(3,'My Debts'!$J$10:$J$19,0) | T6: =N(INDEX('My Debts'!$D$10:$D$19,S$6))/100 | U6: =IF(INDEX('My Debts'!$B$10:$B$19,S$6)="",0,N(INDEX('My Debts'!$E$10:$E$19,S$6))) | V6: =IF(INDEX('My Debts'!$B$10:$B$19,S$6)="",0,N(INDEX('My Debts'!$C$10:$C$19,S$6))) | W6: =IF(INDEX('My Debts'!$B$10:$B$19,S$6)="","",INDEX('My Debts'!$B$10:$B$19,S$6)) | Y6: =MATCH(4,'My Debts'!$J$10:$J$19,0) | Z6: =N(INDEX('My Debts'!$D$10:$D$19,Y$6))/100 | AA6: =IF(INDEX('My Debts'!$B$10:$B$19,Y$6)="",0,N(INDEX('My Debts'!$E$10:$E$19,Y$6))) | AB6: =IF(INDEX('My Debts'!$B$10:$B$19,Y$6)="",0,N(INDEX('My Debts'!$C$10:$C$19,Y$6))) | AC6: =IF(INDEX('My Debts'!$B$10:$B$19,Y$6)="","",INDEX('My Debts'!$B$10:$B$19,Y$6)) | AE6: =MATCH(5,'My Debts'!$J$10:$J$19,0) | AF6: =N(INDEX('My Debts'!$D$10:$D$19,AE$6))/100 | AG6: =IF(INDEX('My Debts'!$B$10:$B$19,AE$6)="",0,N(INDEX('My Debts'!$E$10:$E$19,AE$6))) | AH6: =IF(INDEX('My Debts'!$B$10:$B$19,AE$6)="",0,N(INDEX('My Debts'!$C$10:$C$19,AE$6))) | AI6: =IF(INDEX('My Debts'!$B$10:$B$19,AE$6)="","",INDEX('My Debts'!$B$10:$B$19,AE$6)) | AK6: =MATCH(6,'My Debts'!$J$10:$J$19,0) | AL6: =N(INDEX('My Debts'!$D$10:$D$19,AK$6))/100 | AM6: =IF(INDEX('My Debts'!$B$10:$B$19,AK$6)="",0,N(INDEX('My Debts'!$E$10:$E$19,AK$6))) | AN6: =IF(INDEX('My Debts'!$B$10:$B$19,AK$6)="",0,N(INDEX('My Debts'!$C$10:$C$19,AK$6))) | AO6: =IF(INDEX('My Debts'!$B$10:$B$19,AK$6)="","",INDEX('My Debts'!$B$10:$B$19,AK$6)) | AQ6: =MATCH(7,'My Debts'!$J$10:$J$19,0) | AR6: =N(INDEX('My Debts'!$D$10:$D$19,AQ$6))/100 | AS6: =IF(INDEX('My Debts'!$B$10:$B$19,AQ$6)="",0,N(INDEX('My Debts'!$E$10:$E$19,AQ$6))) | AT6: =IF(INDEX('My Debts'!$B$10:$B$19,AQ$6)="",0,N(INDEX('My Debts'!$C$10:$C$19,AQ$6))) | AU6: =IF(INDEX('My Debts'!$B$10:$B$19,AQ$6)="","",INDEX('My Debts'!$B$10:$B$19,AQ$6)) | AW6: =MATCH(8,'My Debts'!$J$10:$J$19,0) | AX6: =N(INDEX('My Debts'!$D$10:$D$19,AW$6))/100 | AY6: =IF(INDEX('My Debts'!$B$10:$B$19,AW$6)="",0,N(INDEX('My Debts'!$E$10:$E$19,AW$6))) | AZ6: =IF(INDEX('My Debts'!$B$10:$B$19,AW$6)="",0,N(INDEX('My Debts'!$C$10:$C$19,AW$6))) | BA6: =IF(INDEX('My Debts'!$B$10:$B$19,AW$6)="","",INDEX('My Debts'!$B$10:$B$19,AW$6)) | BC6: =MATCH(9,'My Debts'!$J$10:$J$19,0) | BD6: =N(INDEX('My Debts'!$D$10:$D$19,BC$6))/100 | BE6: =IF(INDEX('My Debts'!$B$10:$B$19,BC$6)="",0,N(INDEX('My Debts'!$E$10:$E$19,BC$6))) | BF6: =IF(INDEX('My Debts'!$B$10:$B$19,BC$6)="",0,N(INDEX('My Debts'!$C$10:$C$19,BC$6))) | BG6: =IF(INDEX('My Debts'!$B$10:$B$19,BC$6)="","",INDEX('My Debts'!$B$10:$B$19,BC$6)) | BI6: =MATCH(10,'My Debts'!$J$10:$J$19,0) | BJ6: =N(INDEX('My Debts'!$D$10:$D$19,BI$6))/100 | BK6: =IF(INDEX('My Debts'!$B$10:$B$19,BI$6)="",0,N(INDEX('My Debts'!$E$10:$E$19,BI$6))) | BL6: =IF(INDEX('My Debts'!$B$10:$B$19,BI$6)="",0,N(INDEX('My Debts'!$C$10:$C$19,BI$6))) | BM6: =IF(INDEX('My Debts'!$B$10:$B$19,BI$6)="","",INDEX('My Debts'!$B$10:$B$19,BI$6))
A7: Month | B7: Date | C7: Total owed (end) | D7: Paid this month | E7: Interest this month | G7: Start balance | H7: Interest | I7: Minimum paid | J7: Extra paid | K7: End balance | M7: Start balance | N7: Interest | O7: Minimum paid | P7: Extra paid | Q7: End balance | S7: Start balance | T7: Interest | U7: Minimum paid | V7: Extra paid | W7: End balance | Y7: Start balance | Z7: Interest | AA7: Minimum paid | AB7: Extra paid | AC7: End balance | AE7: Start balance | AF7: Interest | AG7: Minimum paid | AH7: Extra paid | AI7: End balance | AK7: Start balance | AL7: Interest | AM7: Minimum paid | AN7: Extra paid | AO7: End balance | AQ7: Start balance | AR7: Interest | AS7: Minimum paid | AT7: Extra paid | AU7: End balance | AW7: Start balance | AX7: Interest | AY7: Minimum paid | AZ7: Extra paid | BA7: End balance | BC7: Start balance | BD7: Interest | BE7: Minimum paid | BF7: Extra paid | BG7: End balance | BI7: Start balance | BJ7: Interest | BK7: Minimum paid | BL7: Extra paid | BM7: End balance
A8: 1 | B8: =EDATE('My Debts'!$C$6,A8-1) | C8: =K8+Q8+W8+AC8+AI8+AO8+AU8+BA8+BG8+BM8 | D8: =I8+O8+U8+AA8+AG8+AM8+AS8+AY8+BE8+BK8+J8+P8+V8+AB8+AH8+AN8+AT8+AZ8+BF8+BL8 | E8: =H8+N8+T8+Z8+AF8+AL8+AR8+AX8+BD8+BJ8 | F8: =MAX(0,'My Debts'!$E$21-(I8+O8+U8+AA8+AG8+AM8+AS8+AY8+BE8+BK8)) | G8: =J$6 | H8: =ROUND(G8*H$6/12,2) | I8: =MIN(I$6,G8+H8) | J8: =MAX(0,MIN(G8+H8-I8,$F8)) | K8: =ROUND(G8+H8-I8-J8,2) | L8: =$F8-J8 | M8: =P$6 | N8: =ROUND(M8*N$6/12,2) | O8: =MIN(O$6,M8+N8) | P8: =MAX(0,MIN(M8+N8-O8,L8)) | Q8: =ROUND(M8+N8-O8-P8,2) | R8: =L8-P8 | S8: =V$6 | T8: =ROUND(S8*T$6/12,2) | U8: =MIN(U$6,S8+T8) | V8: =MAX(0,MIN(S8+T8-U8,R8)) | W8: =ROUND(S8+T8-U8-V8,2) | X8: =R8-V8 | Y8: =AB$6 | Z8: =ROUND(Y8*Z$6/12,2) | AA8: =MIN(AA$6,Y8+Z8) | AB8: =MAX(0,MIN(Y8+Z8-AA8,X8)) | AC8: =ROUND(Y8+Z8-AA8-AB8,2) | AD8: =X8-AB8 | AE8: =AH$6 | AF8: =ROUND(AE8*AF$6/12,2) | AG8: =MIN(AG$6,AE8+AF8) | AH8: =MAX(0,MIN(AE8+AF8-AG8,AD8)) | AI8: =ROUND(AE8+AF8-AG8-AH8,2) | AJ8: =AD8-AH8 | AK8: =AN$6 | AL8: =ROUND(AK8*AL$6/12,2) | AM8: =MIN(AM$6,AK8+AL8) | AN8: =MAX(0,MIN(AK8+AL8-AM8,AJ8)) | AO8: =ROUND(AK8+AL8-AM8-AN8,2) | AP8: =AJ8-AN8 | AQ8: =AT$6 | AR8: =ROUND(AQ8*AR$6/12,2) | AS8: =MIN(AS$6,AQ8+AR8) | AT8: =MAX(0,MIN(AQ8+AR8-AS8,AP8)) | AU8: =ROUND(AQ8+AR8-AS8-AT8,2) | AV8: =AP8-AT8 | AW8: =AZ$6 | AX8: =ROUND(AW8*AX$6/12,2) | AY8: =MIN(AY$6,AW8+AX8) | AZ8: =MAX(0,MIN(AW8+AX8-AY8,AV8)) | BA8: =ROUND(AW8+AX8-AY8-AZ8,2) | BB8: =AV8-AZ8 | BC8: =BF$6 | BD8: =ROUND(BC8*BD$6/12,2) | BE8: =MIN(BE$6,BC8+BD8) | BF8: =MAX(0,MIN(BC8+BD8-BE8,BB8)) | BG8: =ROUND(BC8+BD8-BE8-BF8,2) | BH8: =BB8-BF8 | BI8: =BL$6 | BJ8: =ROUND(BI8*BJ$6/12,2) | BK8: =MIN(BK$6,BI8+BJ8) | BL8: =MAX(0,MIN(BI8+BJ8-BK8,BH8)) | BM8: =ROUND(BI8+BJ8-BK8-BL8,2) | BN8: =BH8-BL8
A9: 2 | B9: =EDATE('My Debts'!$C$6,A9-1) | C9: =K9+Q9+W9+AC9+AI9+AO9+AU9+BA9+BG9+BM9 | D9: =I9+O9+U9+AA9+AG9+AM9+AS9+AY9+BE9+BK9+J9+P9+V9+AB9+AH9+AN9+AT9+AZ9+BF9+BL9 | E9: =H9+N9+T9+Z9+AF9+AL9+AR9+AX9+BD9+BJ9 | F9: =MAX(0,'My Debts'!$E$21-(I9+O9+U9+AA9+AG9+AM9+AS9+AY9+BE9+BK9)) | G9: =K8 | H9: =ROUND(G9*H$6/12,2) | I9: =MIN(I$6,G9+H9) | J9: =MAX(0,MIN(G9+H9-I9,$F9)) | K9: =ROUND(G9+H9-I9-J9,2) | L9: =$F9-J9 | M9: =Q8 | N9: =ROUND(M9*N$6/12,2) | O9: =MIN(O$6,M9+N9) | P9: =MAX(0,MIN(M9+N9-O9,L9)) | Q9: =ROUND(M9+N9-O9-P9,2) | R9: =L9-P9 | S9: =W8 | T9: =ROUND(S9*T$6/12,2) | U9: =MIN(U$6,S9+T9) | V9: =MAX(0,MIN(S9+T9-U9,R9)) | W9: =ROUND(S9+T9-U9-V9,2) | X9: =R9-V9 | Y9: =AC8 | Z9: =ROUND(Y9*Z$6/12,2) | AA9: =MIN(AA$6,Y9+Z9) | AB9: =MAX(0,MIN(Y9+Z9-AA9,X9)) | AC9: =ROUND(Y9+Z9-AA9-AB9,2) | AD9: =X9-AB9 | AE9: =AI8 | AF9: =ROUND(AE9*AF$6/12,2) | AG9: =MIN(AG$6,AE9+AF9) | AH9: =MAX(0,MIN(AE9+AF9-AG9,AD9)) | AI9: =ROUND(AE9+AF9-AG9-AH9,2) | AJ9: =AD9-AH9 | AK9: =AO8 | AL9: =ROUND(AK9*AL$6/12,2) | AM9: =MIN(AM$6,AK9+AL9) | AN9: =MAX(0,MIN(AK9+AL9-AM9,AJ9)) | AO9: =ROUND(AK9+AL9-AM9-AN9,2) | AP9: =AJ9-AN9 | AQ9: =AU8 | AR9: =ROUND(AQ9*AR$6/12,2) | AS9: =MIN(AS$6,AQ9+AR9) | AT9: =MAX(0,MIN(AQ9+AR9-AS9,AP9)) | AU9: =ROUND(AQ9+AR9-AS9-AT9,2) | AV9: =AP9-AT9 | AW9: =BA8 | AX9: =ROUND(AW9*AX$6/12,2) | AY9: =MIN(AY$6,AW9+AX9) | AZ9: =MAX(0,MIN(AW9+AX9-AY9,AV9)) | BA9: =ROUND(AW9+AX9-AY9-AZ9,2) | BB9: =AV9-AZ9 | BC9: =BG8 | BD9: =ROUND(BC9*BD$6/12,2) | BE9: =MIN(BE$6,BC9+BD9) | BF9: =MAX(0,MIN(BC9+BD9-BE9,BB9)) | BG9: =ROUND(BC9+BD9-BE9-BF9,2) | BH9: =BB9-BF9 | BI9: =BM8 | BJ9: =ROUND(BI9*BJ$6/12,2) | BK9: =MIN(BK$6,BI9+BJ9) | BL9: =MAX(0,MIN(BI9+BJ9-BK9,BH9)) | BM9: =ROUND(BI9+BJ9-BK9-BL9,2) | BN9: =BH9-BL9
A10: 3 | B10: =EDATE('My Debts'!$C$6,A10-1) | C10: =K10+Q10+W10+AC10+AI10+AO10+AU10+BA10+BG10+BM10 | D10: =I10+O10+U10+AA10+AG10+AM10+AS10+AY10+BE10+BK10+J10+P10+V10+AB10+AH10+AN10+AT10+AZ10+BF10+BL10 | E10: =H10+N10+T10+Z10+AF10+AL10+AR10+AX10+BD10+BJ10 | F10: =MAX(0,'My Debts'!$E$21-(I10+O10+U10+AA10+AG10+AM10+AS10+AY10+BE10+BK10)) | G10: =K9 | H10: =ROUND(G10*H$6/12,2) | I10: =MIN(I$6,G10+H10) | J10: =MAX(0,MIN(G10+H10-I10,$F10)) | K10: =ROUND(G10+H10-I10-J10,2) | L10: =$F10-J10 | M10: =Q9 | N10: =ROUND(M10*N$6/12,2) | O10: =MIN(O$6,M10+N10) | P10: =MAX(0,MIN(M10+N10-O10,L10)) | Q10: =ROUND(M10+N10-O10-P10,2) | R10: =L10-P10 | S10: =W9 | T10: =ROUND(S10*T$6/12,2) | U10: =MIN(U$6,S10+T10) | V10: =MAX(0,MIN(S10+T10-U10,R10)) | W10: =ROUND(S10+T10-U10-V10,2) | X10: =R10-V10 | Y10: =AC9 | Z10: =ROUND(Y10*Z$6/12,2) | AA10: =MIN(AA$6,Y10+Z10) | AB10: =MAX(0,MIN(Y10+Z10-AA10,X10)) | AC10: =ROUND(Y10+Z10-AA10-AB10,2) | AD10: =X10-AB10 | AE10: =AI9 | AF10: =ROUND(AE10*AF$6/12,2) | AG10: =MIN(AG$6,AE10+AF10) | AH10: =MAX(0,MIN(AE10+AF10-AG10,AD10)) | AI10: =ROUND(AE10+AF10-AG10-AH10,2) | AJ10: =AD10-AH10 | AK10: =AO9 | AL10: =ROUND(AK10*AL$6/12,2) | AM10: =MIN(AM$6,AK10+AL10) | AN10: =MAX(0,MIN(AK10+AL10-AM10,AJ10)) | AO10: =ROUND(AK10+AL10-AM10-AN10,2) | AP10: =AJ10-AN10 | AQ10: =AU9 | AR10: =ROUND(AQ10*AR$6/12,2) | AS10: =MIN(AS$6,AQ10+AR10) | AT10: =MAX(0,MIN(AQ10+AR10-AS10,AP10)) | AU10: =ROUND(AQ10+AR10-AS10-AT10,2) | AV10: =AP10-AT10 | AW10: =BA9 | AX10: =ROUND(AW10*AX$6/12,2) | AY10: =MIN(AY$6,AW10+AX10) | AZ10: =MAX(0,MIN(AW10+AX10-AY10,AV10)) | BA10: =ROUND(AW10+AX10-AY10-AZ10,2) | BB10: =AV10-AZ10 | BC10: =BG9 | BD10: =ROUND(BC10*BD$6/12,2) | BE10: =MIN(BE$6,BC10+BD10) | BF10: =MAX(0,MIN(BC10+BD10-BE10,BB10)) | BG10: =ROUND(BC10+BD10-BE10-BF10,2) | BH10: =BB10-BF10 | BI10: =BM9 | BJ10: =ROUND(BI10*BJ$6/12,2) | BK10: =MIN(BK$6,BI10+BJ10) | BL10: =MAX(0,MIN(BI10+BJ10-BK10,BH10)) | BM10: =ROUND(BI10+BJ10-BK10-BL10,2) | BN10: =BH10-BL10
A11: 4 | B11: =EDATE('My Debts'!$C$6,A11-1) | C11: =K11+Q11+W11+AC11+AI11+AO11+AU11+BA11+BG11+BM11 | D11: =I11+O11+U11+AA11+AG11+AM11+AS11+AY11+BE11+BK11+J11+P11+V11+AB11+AH11+AN11+AT11+AZ11+BF11+BL11 | E11: =H11+N11+T11+Z11+AF11+AL11+AR11+AX11+BD11+BJ11 | F11: =MAX(0,'My Debts'!$E$21-(I11+O11+U11+AA11+AG11+AM11+AS11+AY11+BE11+BK11)) | G11: =K10 | H11: =ROUND(G11*H$6/12,2) | I11: =MIN(I$6,G11+H11) | J11: =MAX(0,MIN(G11+H11-I11,$F11)) | K11: =ROUND(G11+H11-I11-J11,2) | L11: =$F11-J11 | M11: =Q10 | N11: =ROUND(M11*N$6/12,2) | O11: =MIN(O$6,M11+N11) | P11: =MAX(0,MIN(M11+N11-O11,L11)) | Q11: =ROUND(M11+N11-O11-P11,2) | R11: =L11-P11 | S11: =W10 | T11: =ROUND(S11*T$6/12,2) | U11: =MIN(U$6,S11+T11) | V11: =MAX(0,MIN(S11+T11-U11,R11)) | W11: =ROUND(S11+T11-U11-V11,2) | X11: =R11-V11 | Y11: =AC10 | Z11: =ROUND(Y11*Z$6/12,2) | AA11: =MIN(AA$6,Y11+Z11) | AB11: =MAX(0,MIN(Y11+Z11-AA11,X11)) | AC11: =ROUND(Y11+Z11-AA11-AB11,2) | AD11: =X11-AB11 | AE11: =AI10 | AF11: =ROUND(AE11*AF$6/12,2) | AG11: =MIN(AG$6,AE11+AF11) | AH11: =MAX(0,MIN(AE11+AF11-AG11,AD11)) | AI11: =ROUND(AE11+AF11-AG11-AH11,2) | AJ11: =AD11-AH11 | AK11: =AO10 | AL11: =ROUND(AK11*AL$6/12,2) | AM11: =MIN(AM$6,AK11+AL11) | AN11: =MAX(0,MIN(AK11+AL11-AM11,AJ11)) | AO11: =ROUND(AK11+AL11-AM11-AN11,2) | AP11: =AJ11-AN11 | AQ11: =AU10 | AR11: =ROUND(AQ11*AR$6/12,2) | AS11: =MIN(AS$6,AQ11+AR11) | AT11: =MAX(0,MIN(AQ11+AR11-AS11,AP11)) | AU11: =ROUND(AQ11+AR11-AS11-AT11,2) | AV11: =AP11-AT11 | AW11: =BA10 | AX11: =ROUND(AW11*AX$6/12,2) | AY11: =MIN(AY$6,AW11+AX11) | AZ11: =MAX(0,MIN(AW11+AX11-AY11,AV11)) | BA11: =ROUND(AW11+AX11-AY11-AZ11,2) | BB11: =AV11-AZ11 | BC11: =BG10 | BD11: =ROUND(BC11*BD$6/12,2) | BE11: =MIN(BE$6,BC11+BD11) | BF11: =MAX(0,MIN(BC11+BD11-BE11,BB11)) | BG11: =ROUND(BC11+BD11-BE11-BF11,2) | BH11: =BB11-BF11 | BI11: =BM10 | BJ11: =ROUND(BI11*BJ$6/12,2) | BK11: =MIN(BK$6,BI11+BJ11) | BL11: =MAX(0,MIN(BI11+BJ11-BK11,BH11)) | BM11: =ROUND(BI11+BJ11-BK11-BL11,2) | BN11: =BH11-BL11
A12: 5 | B12: =EDATE('My Debts'!$C$6,A12-1) | C12: =K12+Q12+W12+AC12+AI12+AO12+AU12+BA12+BG12+BM12 | D12: =I12+O12+U12+AA12+AG12+AM12+AS12+AY12+BE12+BK12+J12+P12+V12+AB12+AH12+AN12+AT12+AZ12+BF12+BL12 | E12: =H12+N12+T12+Z12+AF12+AL12+AR12+AX12+BD12+BJ12 | F12: =MAX(0,'My Debts'!$E$21-(I12+O12+U12+AA12+AG12+AM12+AS12+AY12+BE12+BK12)) | G12: =K11 | H12: =ROUND(G12*H$6/12,2) | I12: =MIN(I$6,G12+H12) | J12: =MAX(0,MIN(G12+H12-I12,$F12)) | K12: =ROUND(G12+H12-I12-J12,2) | L12: =$F12-J12 | M12: =Q11 | N12: =ROUND(M12*N$6/12,2) | O12: =MIN(O$6,M12+N12) | P12: =MAX(0,MIN(M12+N12-O12,L12)) | Q12: =ROUND(M12+N12-O12-P12,2) | R12: =L12-P12 | S12: =W11 | T12: =ROUND(S12*T$6/12,2) | U12: =MIN(U$6,S12+T12) | V12: =MAX(0,MIN(S12+T12-U12,R12)) | W12: =ROUND(S12+T12-U12-V12,2) | X12: =R12-V12 | Y12: =AC11 | Z12: =ROUND(Y12*Z$6/12,2) | AA12: =MIN(AA$6,Y12+Z12) | AB12: =MAX(0,MIN(Y12+Z12-AA12,X12)) | AC12: =ROUND(Y12+Z12-AA12-AB12,2) | AD12: =X12-AB12 | AE12: =AI11 | AF12: =ROUND(AE12*AF$6/12,2) | AG12: =MIN(AG$6,AE12+AF12) | AH12: =MAX(0,MIN(AE12+AF12-AG12,AD12)) | AI12: =ROUND(AE12+AF12-AG12-AH12,2) | AJ12: =AD12-AH12 | AK12: =AO11 | AL12: =ROUND(AK12*AL$6/12,2) | AM12: =MIN(AM$6,AK12+AL12) | AN12: =MAX(0,MIN(AK12+AL12-AM12,AJ12)) | AO12: =ROUND(AK12+AL12-AM12-AN12,2) | AP12: =AJ12-AN12 | AQ12: =AU11 | AR12: =ROUND(AQ12*AR$6/12,2) | AS12: =MIN(AS$6,AQ12+AR12) | AT12: =MAX(0,MIN(AQ12+AR12-AS12,AP12)) | AU12: =ROUND(AQ12+AR12-AS12-AT12,2) | AV12: =AP12-AT12 | AW12: =BA11 | AX12: =ROUND(AW12*AX$6/12,2) | AY12: =MIN(AY$6,AW12+AX12) | AZ12: =MAX(0,MIN(AW12+AX12-AY12,AV12)) | BA12: =ROUND(AW12+AX12-AY12-AZ12,2) | BB12: =AV12-AZ12 | BC12: =BG11 | BD12: =ROUND(BC12*BD$6/12,2) | BE12: =MIN(BE$6,BC12+BD12) | BF12: =MAX(0,MIN(BC12+BD12-BE12,BB12)) | BG12: =ROUND(BC12+BD12-BE12-BF12,2) | BH12: =BB12-BF12 | BI12: =BM11 | BJ12: =ROUND(BI12*BJ$6/12,2) | BK12: =MIN(BK$6,BI12+BJ12) | BL12: =MAX(0,MIN(BI12+BJ12-BK12,BH12)) | BM12: =ROUND(BI12+BJ12-BK12-BL12,2) | BN12: =BH12-BL12
A13: 6 | B13: =EDATE('My Debts'!$C$6,A13-1) | C13: =K13+Q13+W13+AC13+AI13+AO13+AU13+BA13+BG13+BM13 | D13: =I13+O13+U13+AA13+AG13+AM13+AS13+AY13+BE13+BK13+J13+P13+V13+AB13+AH13+AN13+AT13+AZ13+BF13+BL13 | E13: =H13+N13+T13+Z13+AF13+AL13+AR13+AX13+BD13+BJ13 | F13: =MAX(0,'My Debts'!$E$21-(I13+O13+U13+AA13+AG13+AM13+AS13+AY13+BE13+BK13)) | G13: =K12 | H13: =ROUND(G13*H$6/12,2) | I13: =MIN(I$6,G13+H13) | J13: =MAX(0,MIN(G13+H13-I13,$F13)) | K13: =ROUND(G13+H13-I13-J13,2) | L13: =$F13-J13 | M13: =Q12 | N13: =ROUND(M13*N$6/12,2) | O13: =MIN(O$6,M13+N13) | P13: =MAX(0,MIN(M13+N13-O13,L13)) | Q13: =ROUND(M13+N13-O13-P13,2) | R13: =L13-P13 | S13: =W12 | T13: =ROUND(S13*T$6/12,2) | U13: =MIN(U$6,S13+T13) | V13: =MAX(0,MIN(S13+T13-U13,R13)) | W13: =ROUND(S13+T13-U13-V13,2) | X13: =R13-V13 | Y13: =AC12 | Z13: =ROUND(Y13*Z$6/12,2) | AA13: =MIN(AA$6,Y13+Z13) | AB13: =MAX(0,MIN(Y13+Z13-AA13,X13)) | AC13: =ROUND(Y13+Z13-AA13-AB13,2) | AD13: =X13-AB13 | AE13: =AI12 | AF13: =ROUND(AE13*AF$6/12,2) | AG13: =MIN(AG$6,AE13+AF13) | AH13: =MAX(0,MIN(AE13+AF13-AG13,AD13)) | AI13: =ROUND(AE13+AF13-AG13-AH13,2) | AJ13: =AD13-AH13 | AK13: =AO12 | AL13: =ROUND(AK13*AL$6/12,2) | AM13: =MIN(AM$6,AK13+AL13) | AN13: =MAX(0,MIN(AK13+AL13-AM13,AJ13)) | AO13: =ROUND(AK13+AL13-AM13-AN13,2) | AP13: =AJ13-AN13 | AQ13: =AU12 | AR13: =ROUND(AQ13*AR$6/12,2) | AS13: =MIN(AS$6,AQ13+AR13) | AT13: =MAX(0,MIN(AQ13+AR13-AS13,AP13)) | AU13: =ROUND(AQ13+AR13-AS13-AT13,2) | AV13: =AP13-AT13 | AW13: =BA12 | AX13: =ROUND(AW13*AX$6/12,2) | AY13: =MIN(AY$6,AW13+AX13) | AZ13: =MAX(0,MIN(AW13+AX13-AY13,AV13)) | BA13: =ROUND(AW13+AX13-AY13-AZ13,2) | BB13: =AV13-AZ13 | BC13: =BG12 | BD13: =ROUND(BC13*BD$6/12,2) | BE13: =MIN(BE$6,BC13+BD13) | BF13: =MAX(0,MIN(BC13+BD13-BE13,BB13)) | BG13: =ROUND(BC13+BD13-BE13-BF13,2) | BH13: =BB13-BF13 | BI13: =BM12 | BJ13: =ROUND(BI13*BJ$6/12,2) | BK13: =MIN(BK$6,BI13+BJ13) | BL13: =MAX(0,MIN(BI13+BJ13-BK13,BH13)) | BM13: =ROUND(BI13+BJ13-BK13-BL13,2) | BN13: =BH13-BL13
A14: 7 | B14: =EDATE('My Debts'!$C$6,A14-1) | C14: =K14+Q14+W14+AC14+AI14+AO14+AU14+BA14+BG14+BM14 | D14: =I14+O14+U14+AA14+AG14+AM14+AS14+AY14+BE14+BK14+J14+P14+V14+AB14+AH14+AN14+AT14+AZ14+BF14+BL14 | E14: =H14+N14+T14+Z14+AF14+AL14+AR14+AX14+BD14+BJ14 | F14: =MAX(0,'My Debts'!$E$21-(I14+O14+U14+AA14+AG14+AM14+AS14+AY14+BE14+BK14)) | G14: =K13 | H14: =ROUND(G14*H$6/12,2) | I14: =MIN(I$6,G14+H14) | J14: =MAX(0,MIN(G14+H14-I14,$F14)) | K14: =ROUND(G14+H14-I14-J14,2) | L14: =$F14-J14 | M14: =Q13 | N14: =ROUND(M14*N$6/12,2) | O14: =MIN(O$6,M14+N14) | P14: =MAX(0,MIN(M14+N14-O14,L14)) | Q14: =ROUND(M14+N14-O14-P14,2) | R14: =L14-P14 | S14: =W13 | T14: =ROUND(S14*T$6/12,2) | U14: =MIN(U$6,S14+T14) | V14: =MAX(0,MIN(S14+T14-U14,R14)) | W14: =ROUND(S14+T14-U14-V14,2) | X14: =R14-V14 | Y14: =AC13 | Z14: =ROUND(Y14*Z$6/12,2) | AA14: =MIN(AA$6,Y14+Z14) | AB14: =MAX(0,MIN(Y14+Z14-AA14,X14)) | AC14: =ROUND(Y14+Z14-AA14-AB14,2) | AD14: =X14-AB14 | AE14: =AI13 | AF14: =ROUND(AE14*AF$6/12,2) | AG14: =MIN(AG$6,AE14+AF14) | AH14: =MAX(0,MIN(AE14+AF14-AG14,AD14)) | AI14: =ROUND(AE14+AF14-AG14-AH14,2) | AJ14: =AD14-AH14 | AK14: =AO13 | AL14: =ROUND(AK14*AL$6/12,2) | AM14: =MIN(AM$6,AK14+AL14) | AN14: =MAX(0,MIN(AK14+AL14-AM14,AJ14)) | AO14: =ROUND(AK14+AL14-AM14-AN14,2) | AP14: =AJ14-AN14 | AQ14: =AU13 | AR14: =ROUND(AQ14*AR$6/12,2) | AS14: =MIN(AS$6,AQ14+AR14) | AT14: =MAX(0,MIN(AQ14+AR14-AS14,AP14)) | AU14: =ROUND(AQ14+AR14-AS14-AT14,2) | AV14: =AP14-AT14 | AW14: =BA13 | AX14: =ROUND(AW14*AX$6/12,2) | AY14: =MIN(AY$6,AW14+AX14) | AZ14: =MAX(0,MIN(AW14+AX14-AY14,AV14)) | BA14: =ROUND(AW14+AX14-AY14-AZ14,2) | BB14: =AV14-AZ14 | BC14: =BG13 | BD14: =ROUND(BC14*BD$6/12,2) | BE14: =MIN(BE$6,BC14+BD14) | BF14: =MAX(0,MIN(BC14+BD14-BE14,BB14)) | BG14: =ROUND(BC14+BD14-BE14-BF14,2) | BH14: =BB14-BF14 | BI14: =BM13 | BJ14: =ROUND(BI14*BJ$6/12,2) | BK14: =MIN(BK$6,BI14+BJ14) | BL14: =MAX(0,MIN(BI14+BJ14-BK14,BH14)) | BM14: =ROUND(BI14+BJ14-BK14-BL14,2) | BN14: =BH14-BL14
A15: 8 | B15: =EDATE('My Debts'!$C$6,A15-1) | C15: =K15+Q15+W15+AC15+AI15+AO15+AU15+BA15+BG15+BM15 | D15: =I15+O15+U15+AA15+AG15+AM15+AS15+AY15+BE15+BK15+J15+P15+V15+AB15+AH15+AN15+AT15+AZ15+BF15+BL15 | E15: =H15+N15+T15+Z15+AF15+AL15+AR15+AX15+BD15+BJ15 | F15: =MAX(0,'My Debts'!$E$21-(I15+O15+U15+AA15+AG15+AM15+AS15+AY15+BE15+BK15)) | G15: =K14 | H15: =ROUND(G15*H$6/12,2) | I15: =MIN(I$6,G15+H15) | J15: =MAX(0,MIN(G15+H15-I15,$F15)) | K15: =ROUND(G15+H15-I15-J15,2) | L15: =$F15-J15 | M15: =Q14 | N15: =ROUND(M15*N$6/12,2) | O15: =MIN(O$6,M15+N15) | P15: =MAX(0,MIN(M15+N15-O15,L15)) | Q15: =ROUND(M15+N15-O15-P15,2) | R15: =L15-P15 | S15: =W14 | T15: =ROUND(S15*T$6/12,2) | U15: =MIN(U$6,S15+T15) | V15: =MAX(0,MIN(S15+T15-U15,R15)) | W15: =ROUND(S15+T15-U15-V15,2) | X15: =R15-V15 | Y15: =AC14 | Z15: =ROUND(Y15*Z$6/12,2) | AA15: =MIN(AA$6,Y15+Z15) | AB15: =MAX(0,MIN(Y15+Z15-AA15,X15)) | AC15: =ROUND(Y15+Z15-AA15-AB15,2) | AD15: =X15-AB15 | AE15: =AI14 | AF15: =ROUND(AE15*AF$6/12,2) | AG15: =MIN(AG$6,AE15+AF15) | AH15: =MAX(0,MIN(AE15+AF15-AG15,AD15)) | AI15: =ROUND(AE15+AF15-AG15-AH15,2) | AJ15: =AD15-AH15 | AK15: =AO14 | AL15: =ROUND(AK15*AL$6/12,2) | AM15: =MIN(AM$6,AK15+AL15) | AN15: =MAX(0,MIN(AK15+AL15-AM15,AJ15)) | AO15: =ROUND(AK15+AL15-AM15-AN15,2) | AP15: =AJ15-AN15 | AQ15: =AU14 | AR15: =ROUND(AQ15*AR$6/12,2) | AS15: =MIN(AS$6,AQ15+AR15) | AT15: =MAX(0,MIN(AQ15+AR15-AS15,AP15)) | AU15: =ROUND(AQ15+AR15-AS15-AT15,2) | AV15: =AP15-AT15 | AW15: =BA14 | AX15: =ROUND(AW15*AX$6/12,2) | AY15: =MIN(AY$6,AW15+AX15) | AZ15: =MAX(0,MIN(AW15+AX15-AY15,AV15)) | BA15: =ROUND(AW15+AX15-AY15-AZ15,2) | BB15: =AV15-AZ15 | BC15: =BG14 | BD15: =ROUND(BC15*BD$6/12,2) | BE15: =MIN(BE$6,BC15+BD15) | BF15: =MAX(0,MIN(BC15+BD15-BE15,BB15)) | BG15: =ROUND(BC15+BD15-BE15-BF15,2) | BH15: =BB15-BF15 | BI15: =BM14 | BJ15: =ROUND(BI15*BJ$6/12,2) | BK15: =MIN(BK$6,BI15+BJ15) | BL15: =MAX(0,MIN(BI15+BJ15-BK15,BH15)) | BM15: =ROUND(BI15+BJ15-BK15-BL15,2) | BN15: =BH15-BL15
A16: 9 | B16: =EDATE('My Debts'!$C$6,A16-1) | C16: =K16+Q16+W16+AC16+AI16+AO16+AU16+BA16+BG16+BM16 | D16: =I16+O16+U16+AA16+AG16+AM16+AS16+AY16+BE16+BK16+J16+P16+V16+AB16+AH16+AN16+AT16+AZ16+BF16+BL16 | E16: =H16+N16+T16+Z16+AF16+AL16+AR16+AX16+BD16+BJ16 | F16: =MAX(0,'My Debts'!$E$21-(I16+O16+U16+AA16+AG16+AM16+AS16+AY16+BE16+BK16)) | G16: =K15 | H16: =ROUND(G16*H$6/12,2) | I16: =MIN(I$6,G16+H16) | J16: =MAX(0,MIN(G16+H16-I16,$F16)) | K16: =ROUND(G16+H16-I16-J16,2) | L16: =$F16-J16 | M16: =Q15 | N16: =ROUND(M16*N$6/12,2) | O16: =MIN(O$6,M16+N16) | P16: =MAX(0,MIN(M16+N16-O16,L16)) | Q16: =ROUND(M16+N16-O16-P16,2) | R16: =L16-P16 | S16: =W15 | T16: =ROUND(S16*T$6/12,2) | U16: =MIN(U$6,S16+T16) | V16: =MAX(0,MIN(S16+T16-U16,R16)) | W16: =ROUND(S16+T16-U16-V16,2) | X16: =R16-V16 | Y16: =AC15 | Z16: =ROUND(Y16*Z$6/12,2) | AA16: =MIN(AA$6,Y16+Z16) | AB16: =MAX(0,MIN(Y16+Z16-AA16,X16)) | AC16: =ROUND(Y16+Z16-AA16-AB16,2) | AD16: =X16-AB16 | AE16: =AI15 | AF16: =ROUND(AE16*AF$6/12,2) | AG16: =MIN(AG$6,AE16+AF16) | AH16: =MAX(0,MIN(AE16+AF16-AG16,AD16)) | AI16: =ROUND(AE16+AF16-AG16-AH16,2) | AJ16: =AD16-AH16 | AK16: =AO15 | AL16: =ROUND(AK16*AL$6/12,2) | AM16: =MIN(AM$6,AK16+AL16) | AN16: =MAX(0,MIN(AK16+AL16-AM16,AJ16)) | AO16: =ROUND(AK16+AL16-AM16-AN16,2) | AP16: =AJ16-AN16 | AQ16: =AU15 | AR16: =ROUND(AQ16*AR$6/12,2) | AS16: =MIN(AS$6,AQ16+AR16) | AT16: =MAX(0,MIN(AQ16+AR16-AS16,AP16)) | AU16: =ROUND(AQ16+AR16-AS16-AT16,2) | AV16: =AP16-AT16 | AW16: =BA15 | AX16: =ROUND(AW16*AX$6/12,2) | AY16: =MIN(AY$6,AW16+AX16) | AZ16: =MAX(0,MIN(AW16+AX16-AY16,AV16)) | BA16: =ROUND(AW16+AX16-AY16-AZ16,2) | BB16: =AV16-AZ16 | BC16: =BG15 | BD16: =ROUND(BC16*BD$6/12,2) | BE16: =MIN(BE$6,BC16+BD16) | BF16: =MAX(0,MIN(BC16+BD16-BE16,BB16)) | BG16: =ROUND(BC16+BD16-BE16-BF16,2) | BH16: =BB16-BF16 | BI16: =BM15 | BJ16: =ROUND(BI16*BJ$6/12,2) | BK16: =MIN(BK$6,BI16+BJ16) | BL16: =MAX(0,MIN(BI16+BJ16-BK16,BH16)) | BM16: =ROUND(BI16+BJ16-BK16-BL16,2) | BN16: =BH16-BL16
A17: 10 | B17: =EDATE('My Debts'!$C$6,A17-1) | C17: =K17+Q17+W17+AC17+AI17+AO17+AU17+BA17+BG17+BM17 | D17: =I17+O17+U17+AA17+AG17+AM17+AS17+AY17+BE17+BK17+J17+P17+V17+AB17+AH17+AN17+AT17+AZ17+BF17+BL17 | E17: =H17+N17+T17+Z17+AF17+AL17+AR17+AX17+BD17+BJ17 | F17: =MAX(0,'My Debts'!$E$21-(I17+O17+U17+AA17+AG17+AM17+AS17+AY17+BE17+BK17)) | G17: =K16 | H17: =ROUND(G17*H$6/12,2) | I17: =MIN(I$6,G17+H17) | J17: =MAX(0,MIN(G17+H17-I17,$F17)) | K17: =ROUND(G17+H17-I17-J17,2) | L17: =$F17-J17 | M17: =Q16 | N17: =ROUND(M17*N$6/12,2) | O17: =MIN(O$6,M17+N17) | P17: =MAX(0,MIN(M17+N17-O17,L17)) | Q17: =ROUND(M17+N17-O17-P17,2) | R17: =L17-P17 | S17: =W16 | T17: =ROUND(S17*T$6/12,2) | U17: =MIN(U$6,S17+T17) | V17: =MAX(0,MIN(S17+T17-U17,R17)) | W17: =ROUND(S17+T17-U17-V17,2) | X17: =R17-V17 | Y17: =AC16 | Z17: =ROUND(Y17*Z$6/12,2) | AA17: =MIN(AA$6,Y17+Z17) | AB17: =MAX(0,MIN(Y17+Z17-AA17,X17)) | AC17: =ROUND(Y17+Z17-AA17-AB17,2) | AD17: =X17-AB17 | AE17: =AI16 | AF17: =ROUND(AE17*AF$6/12,2) | AG17: =MIN(AG$6,AE17+AF17) | AH17: =MAX(0,MIN(AE17+AF17-AG17,AD17)) | AI17: =ROUND(AE17+AF17-AG17-AH17,2) | AJ17: =AD17-AH17 | AK17: =AO16 | AL17: =ROUND(AK17*AL$6/12,2) | AM17: =MIN(AM$6,AK17+AL17) | AN17: =MAX(0,MIN(AK17+AL17-AM17,AJ17)) | AO17: =ROUND(AK17+AL17-AM17-AN17,2) | AP17: =AJ17-AN17 | AQ17: =AU16 | AR17: =ROUND(AQ17*AR$6/12,2) | AS17: =MIN(AS$6,AQ17+AR17) | AT17: =MAX(0,MIN(AQ17+AR17-AS17,AP17)) | AU17: =ROUND(AQ17+AR17-AS17-AT17,2) | AV17: =AP17-AT17 | AW17: =BA16 | AX17: =ROUND(AW17*AX$6/12,2) | AY17: =MIN(AY$6,AW17+AX17) | AZ17: =MAX(0,MIN(AW17+AX17-AY17,AV17)) | BA17: =ROUND(AW17+AX17-AY17-AZ17,2) | BB17: =AV17-AZ17 | BC17: =BG16 | BD17: =ROUND(BC17*BD$6/12,2) | BE17: =MIN(BE$6,BC17+BD17) | BF17: =MAX(0,MIN(BC17+BD17-BE17,BB17)) | BG17: =ROUND(BC17+BD17-BE17-BF17,2) | BH17: =BB17-BF17 | BI17: =BM16 | BJ17: =ROUND(BI17*BJ$6/12,2) | BK17: =MIN(BK$6,BI17+BJ17) | BL17: =MAX(0,MIN(BI17+BJ17-BK17,BH17)) | BM17: =ROUND(BI17+BJ17-BK17-BL17,2) | BN17: =BH17-BL17
A18: 11 | B18: =EDATE('My Debts'!$C$6,A18-1) | C18: =K18+Q18+W18+AC18+AI18+AO18+AU18+BA18+BG18+BM18 | D18: =I18+O18+U18+AA18+AG18+AM18+AS18+AY18+BE18+BK18+J18+P18+V18+AB18+AH18+AN18+AT18+AZ18+BF18+BL18 | E18: =H18+N18+T18+Z18+AF18+AL18+AR18+AX18+BD18+BJ18 | F18: =MAX(0,'My Debts'!$E$21-(I18+O18+U18+AA18+AG18+AM18+AS18+AY18+BE18+BK18)) | G18: =K17 | H18: =ROUND(G18*H$6/12,2) | I18: =MIN(I$6,G18+H18) | J18: =MAX(0,MIN(G18+H18-I18,$F18)) | K18: =ROUND(G18+H18-I18-J18,2) | L18: =$F18-J18 | M18: =Q17 | N18: =ROUND(M18*N$6/12,2) | O18: =MIN(O$6,M18+N18) | P18: =MAX(0,MIN(M18+N18-O18,L18)) | Q18: =ROUND(M18+N18-O18-P18,2) | R18: =L18-P18 | S18: =W17 | T18: =ROUND(S18*T$6/12,2) | U18: =MIN(U$6,S18+T18) | V18: =MAX(0,MIN(S18+T18-U18,R18)) | W18: =ROUND(S18+T18-U18-V18,2) | X18: =R18-V18 | Y18: =AC17 | Z18: =ROUND(Y18*Z$6/12,2) | AA18: =MIN(AA$6,Y18+Z18) | AB18: =MAX(0,MIN(Y18+Z18-AA18,X18)) | AC18: =ROUND(Y18+Z18-AA18-AB18,2) | AD18: =X18-AB18 | AE18: =AI17 | AF18: =ROUND(AE18*AF$6/12,2) | AG18: =MIN(AG$6,AE18+AF18) | AH18: =MAX(0,MIN(AE18+AF18-AG18,AD18)) | AI18: =ROUND(AE18+AF18-AG18-AH18,2) | AJ18: =AD18-AH18 | AK18: =AO17 | AL18: =ROUND(AK18*AL$6/12,2) | AM18: =MIN(AM$6,AK18+AL18) | AN18: =MAX(0,MIN(AK18+AL18-AM18,AJ18)) | AO18: =ROUND(AK18+AL18-AM18-AN18,2) | AP18: =AJ18-AN18 | AQ18: =AU17 | AR18: =ROUND(AQ18*AR$6/12,2) | AS18: =MIN(AS$6,AQ18+AR18) | AT18: =MAX(0,MIN(AQ18+AR18-AS18,AP18)) | AU18: =ROUND(AQ18+AR18-AS18-AT18,2) | AV18: =AP18-AT18 | AW18: =BA17 | AX18: =ROUND(AW18*AX$6/12,2) | AY18: =MIN(AY$6,AW18+AX18) | AZ18: =MAX(0,MIN(AW18+AX18-AY18,AV18)) | BA18: =ROUND(AW18+AX18-AY18-AZ18,2) | BB18: =AV18-AZ18 | BC18: =BG17 | BD18: =ROUND(BC18*BD$6/12,2) | BE18: =MIN(BE$6,BC18+BD18) | BF18: =MAX(0,MIN(BC18+BD18-BE18,BB18)) | BG18: =ROUND(BC18+BD18-BE18-BF18,2) | BH18: =BB18-BF18 | BI18: =BM17 | BJ18: =ROUND(BI18*BJ$6/12,2) | BK18: =MIN(BK$6,BI18+BJ18) | BL18: =MAX(0,MIN(BI18+BJ18-BK18,BH18)) | BM18: =ROUND(BI18+BJ18-BK18-BL18,2) | BN18: =BH18-BL18
A19: 12 | B19: =EDATE('My Debts'!$C$6,A19-1) | C19: =K19+Q19+W19+AC19+AI19+AO19+AU19+BA19+BG19+BM19 | D19: =I19+O19+U19+AA19+AG19+AM19+AS19+AY19+BE19+BK19+J19+P19+V19+AB19+AH19+AN19+AT19+AZ19+BF19+BL19 | E19: =H19+N19+T19+Z19+AF19+AL19+AR19+AX19+BD19+BJ19 | F19: =MAX(0,'My Debts'!$E$21-(I19+O19+U19+AA19+AG19+AM19+AS19+AY19+BE19+BK19)) | G19: =K18 | H19: =ROUND(G19*H$6/12,2) | I19: =MIN(I$6,G19+H19) | J19: =MAX(0,MIN(G19+H19-I19,$F19)) | K19: =ROUND(G19+H19-I19-J19,2) | L19: =$F19-J19 | M19: =Q18 | N19: =ROUND(M19*N$6/12,2) | O19: =MIN(O$6,M19+N19) | P19: =MAX(0,MIN(M19+N19-O19,L19)) | Q19: =ROUND(M19+N19-O19-P19,2) | R19: =L19-P19 | S19: =W18 | T19: =ROUND(S19*T$6/12,2) | U19: =MIN(U$6,S19+T19) | V19: =MAX(0,MIN(S19+T19-U19,R19)) | W19: =ROUND(S19+T19-U19-V19,2) | X19: =R19-V19 | Y19: =AC18 | Z19: =ROUND(Y19*Z$6/12,2) | AA19: =MIN(AA$6,Y19+Z19) | AB19: =MAX(0,MIN(Y19+Z19-AA19,X19)) | AC19: =ROUND(Y19+Z19-AA19-AB19,2) | AD19: =X19-AB19 | AE19: =AI18 | AF19: =ROUND(AE19*AF$6/12,2) | AG19: =MIN(AG$6,AE19+AF19) | AH19: =MAX(0,MIN(AE19+AF19-AG19,AD19)) | AI19: =ROUND(AE19+AF19-AG19-AH19,2) | AJ19: =AD19-AH19 | AK19: =AO18 | AL19: =ROUND(AK19*AL$6/12,2) | AM19: =MIN(AM$6,AK19+AL19) | AN19: =MAX(0,MIN(AK19+AL19-AM19,AJ19)) | AO19: =ROUND(AK19+AL19-AM19-AN19,2) | AP19: =AJ19-AN19 | AQ19: =AU18 | AR19: =ROUND(AQ19*AR$6/12,2) | AS19: =MIN(AS$6,AQ19+AR19) | AT19: =MAX(0,MIN(AQ19+AR19-AS19,AP19)) | AU19: =ROUND(AQ19+AR19-AS19-AT19,2) | AV19: =AP19-AT19 | AW19: =BA18 | AX19: =ROUND(AW19*AX$6/12,2) | AY19: =MIN(AY$6,AW19+AX19) | AZ19: =MAX(0,MIN(AW19+AX19-AY19,AV19)) | BA19: =ROUND(AW19+AX19-AY19-AZ19,2) | BB19: =AV19-AZ19 | BC19: =BG18 | BD19: =ROUND(BC19*BD$6/12,2) | BE19: =MIN(BE$6,BC19+BD19) | BF19: =MAX(0,MIN(BC19+BD19-BE19,BB19)) | BG19: =ROUND(BC19+BD19-BE19-BF19,2) | BH19: =BB19-BF19 | BI19: =BM18 | BJ19: =ROUND(BI19*BJ$6/12,2) | BK19: =MIN(BK$6,BI19+BJ19) | BL19: =MAX(0,MIN(BI19+BJ19-BK19,BH19)) | BM19: =ROUND(BI19+BJ19-BK19-BL19,2) | BN19: =BH19-BL19
A20: 13 | B20: =EDATE('My Debts'!$C$6,A20-1) | C20: =K20+Q20+W20+AC20+AI20+AO20+AU20+BA20+BG20+BM20 | D20: =I20+O20+U20+AA20+AG20+AM20+AS20+AY20+BE20+BK20+J20+P20+V20+AB20+AH20+AN20+AT20+AZ20+BF20+BL20 | E20: =H20+N20+T20+Z20+AF20+AL20+AR20+AX20+BD20+BJ20 | F20: =MAX(0,'My Debts'!$E$21-(I20+O20+U20+AA20+AG20+AM20+AS20+AY20+BE20+BK20)) | G20: =K19 | H20: =ROUND(G20*H$6/12,2) | I20: =MIN(I$6,G20+H20) | J20: =MAX(0,MIN(G20+H20-I20,$F20)) | K20: =ROUND(G20+H20-I20-J20,2) | L20: =$F20-J20 | M20: =Q19 | N20: =ROUND(M20*N$6/12,2) | O20: =MIN(O$6,M20+N20) | P20: =MAX(0,MIN(M20+N20-O20,L20)) | Q20: =ROUND(M20+N20-O20-P20,2) | R20: =L20-P20 | S20: =W19 | T20: =ROUND(S20*T$6/12,2) | U20: =MIN(U$6,S20+T20) | V20: =MAX(0,MIN(S20+T20-U20,R20)) | W20: =ROUND(S20+T20-U20-V20,2) | X20: =R20-V20 | Y20: =AC19 | Z20: =ROUND(Y20*Z$6/12,2) | AA20: =MIN(AA$6,Y20+Z20) | AB20: =MAX(0,MIN(Y20+Z20-AA20,X20)) | AC20: =ROUND(Y20+Z20-AA20-AB20,2) | AD20: =X20-AB20 | AE20: =AI19 | AF20: =ROUND(AE20*AF$6/12,2) | AG20: =MIN(AG$6,AE20+AF20) | AH20: =MAX(0,MIN(AE20+AF20-AG20,AD20)) | AI20: =ROUND(AE20+AF20-AG20-AH20,2) | AJ20: =AD20-AH20 | AK20: =AO19 | AL20: =ROUND(AK20*AL$6/12,2) | AM20: =MIN(AM$6,AK20+AL20) | AN20: =MAX(0,MIN(AK20+AL20-AM20,AJ20)) | AO20: =ROUND(AK20+AL20-AM20-AN20,2) | AP20: =AJ20-AN20 | AQ20: =AU19 | AR20: =ROUND(AQ20*AR$6/12,2) | AS20: =MIN(AS$6,AQ20+AR20) | AT20: =MAX(0,MIN(AQ20+AR20-AS20,AP20)) | AU20: =ROUND(AQ20+AR20-AS20-AT20,2) | AV20: =AP20-AT20 | AW20: =BA19 | AX20: =ROUND(AW20*AX$6/12,2) | AY20: =MIN(AY$6,AW20+AX20) | AZ20: =MAX(0,MIN(AW20+AX20-AY20,AV20)) | BA20: =ROUND(AW20+AX20-AY20-AZ20,2) | BB20: =AV20-AZ20 | BC20: =BG19 | BD20: =ROUND(BC20*BD$6/12,2) | BE20: =MIN(BE$6,BC20+BD20) | BF20: =MAX(0,MIN(BC20+BD20-BE20,BB20)) | BG20: =ROUND(BC20+BD20-BE20-BF20,2) | BH20: =BB20-BF20 | BI20: =BM19 | BJ20: =ROUND(BI20*BJ$6/12,2) | BK20: =MIN(BK$6,BI20+BJ20) | BL20: =MAX(0,MIN(BI20+BJ20-BK20,BH20)) | BM20: =ROUND(BI20+BJ20-BK20-BL20,2) | BN20: =BH20-BL20
... A307: 300 | B307: =EDATE('My Debts'!$C$6,A307-1) | C307: =K307+Q307+W307+AC307+AI307+AO307+AU307+BA307+BG307+BM307 | D307: =I307+O307+U307+AA307+AG307+AM307+AS307+AY307+BE307+BK307+J307+P307+V307+AB307+AH307+AN307+AT307+AZ307+BF307+BL307 | E307: =H307+N307+T307+Z307+AF307+AL307+AR307+AX307+BD307+BJ307 | F307: =MAX(0,'My Debts'!$E$21-(I307+O307+U307+AA307+AG307+AM307+AS307+AY307+BE307+BK307)) | G307: =K306 | H307: =ROUND(G307*H$6/12,2) | I307: =MIN(I$6,G307+H307) | J307: =MAX(0,MIN(G307+H307-I307,$F307)) | K307: =ROUND(G307+H307-I307-J307,2) | L307: =$F307-J307 | M307: =Q306 | N307: =ROUND(M307*N$6/12,2) | O307: =MIN(O$6,M307+N307) | P307: =MAX(0,MIN(M307+N307-O307,L307)) | Q307: =ROUND(M307+N307-O307-P307,2) | R307: =L307-P307 | S307: =W306 | T307: =ROUND(S307*T$6/12,2) | U307: =MIN(U$6,S307+T307) | V307: =MAX(0,MIN(S307+T307-U307,R307)) | W307: =ROUND(S307+T307-U307-V307,2) | X307: =R307-V307 | Y307: =AC306 | Z307: =ROUND(Y307*Z$6/12,2) | AA307: =MIN(AA$6,Y307+Z307) | AB307: =MAX(0,MIN(Y307+Z307-AA307,X307)) | AC307: =ROUND(Y307+Z307-AA307-AB307,2) | AD307: =X307-AB307 | AE307: =AI306 | AF307: =ROUND(AE307*AF$6/12,2) | AG307: =MIN(AG$6,AE307+AF307) | AH307: =MAX(0,MIN(AE307+AF307-AG307,AD307)) | AI307: =ROUND(AE307+AF307-AG307-AH307,2) | AJ307: =AD307-AH307 | AK307: =AO306 | AL307: =ROUND(AK307*AL$6/12,2) | AM307: =MIN(AM$6,AK307+AL307) | AN307: =MAX(0,MIN(AK307+AL307-AM307,AJ307)) | AO307: =ROUND(AK307+AL307-AM307-AN307,2) | AP307: =AJ307-AN307 | AQ307: =AU306 | AR307: =ROUND(AQ307*AR$6/12,2) | AS307: =MIN(AS$6,AQ307+AR307) | AT307: =MAX(0,MIN(AQ307+AR307-AS307,AP307)) | AU307: =ROUND(AQ307+AR307-AS307-AT307,2) | AV307: =AP307-AT307 | AW307: =BA306 | AX307: =ROUND(AW307*AX$6/12,2) | AY307: =MIN(AY$6,AW307+AX307) | AZ307: =MAX(0,MIN(AW307+AX307-AY307,AV307)) | BA307: =ROUND(AW307+AX307-AY307-AZ307,2) | BB307: =AV307-AZ307 | BC307: =BG306 | BD307: =ROUND(BC307*BD$6/12,2) | BE307: =MIN(BE$6,BC307+BD307) | BF307: =MAX(0,MIN(BC307+BD307-BE307,BB307)) | BG307: =ROUND(BC307+BD307-BE307-BF307,2) | BH307: =BB307-BF307 | BI307: =BM306 | BJ307: =ROUND(BI307*BJ$6/12,2) | BK307: =MIN(BK$6,BI307+BJ307) | BL307: =MAX(0,MIN(BI307+BJ307-BK307,BH307)) | BM307: =ROUND(BI307+BJ307-BK307-BL307,2) | BN307: =BH307-BL307

Sheet Avalanche
B2: Avalanche schedule
B3: Highest APR first. Each paid-off debt's payment rolls into the next one.
G5: ="Payoff #1: "&IF(K6="","(empty)",K6) | M5: ="Payoff #2: "&IF(Q6="","(empty)",Q6) | S5: ="Payoff #3: "&IF(W6="","(empty)",W6) | Y5: ="Payoff #4: "&IF(AC6="","(empty)",AC6) | AE5: ="Payoff #5: "&IF(AI6="","(empty)",AI6) | AK5: ="Payoff #6: "&IF(AO6="","(empty)",AO6) | AQ5: ="Payoff #7: "&IF(AU6="","(empty)",AU6) | AW5: ="Payoff #8: "&IF(BA6="","(empty)",BA6) | BC5: ="Payoff #9: "&IF(BG6="","(empty)",BG6) | BI5: ="Payoff #10: "&IF(BM6="","(empty)",BM6)
G6: =MATCH(1,'My Debts'!$K$10:$K$19,0) | H6: =N(INDEX('My Debts'!$D$10:$D$19,G$6))/100 | I6: =IF(INDEX('My Debts'!$B$10:$B$19,G$6)="",0,N(INDEX('My Debts'!$E$10:$E$19,G$6))) | J6: =IF(INDEX('My Debts'!$B$10:$B$19,G$6)="",0,N(INDEX('My Debts'!$C$10:$C$19,G$6))) | K6: =IF(INDEX('My Debts'!$B$10:$B$19,G$6)="","",INDEX('My Debts'!$B$10:$B$19,G$6)) | M6: =MATCH(2,'My Debts'!$K$10:$K$19,0) | N6: =N(INDEX('My Debts'!$D$10:$D$19,M$6))/100 | O6: =IF(INDEX('My Debts'!$B$10:$B$19,M$6)="",0,N(INDEX('My Debts'!$E$10:$E$19,M$6))) | P6: =IF(INDEX('My Debts'!$B$10:$B$19,M$6)="",0,N(INDEX('My Debts'!$C$10:$C$19,M$6))) | Q6: =IF(INDEX('My Debts'!$B$10:$B$19,M$6)="","",INDEX('My Debts'!$B$10:$B$19,M$6)) | S6: =MATCH(3,'My Debts'!$K$10:$K$19,0) | T6: =N(INDEX('My Debts'!$D$10:$D$19,S$6))/100 | U6: =IF(INDEX('My Debts'!$B$10:$B$19,S$6)="",0,N(INDEX('My Debts'!$E$10:$E$19,S$6))) | V6: =IF(INDEX('My Debts'!$B$10:$B$19,S$6)="",0,N(INDEX('My Debts'!$C$10:$C$19,S$6))) | W6: =IF(INDEX('My Debts'!$B$10:$B$19,S$6)="","",INDEX('My Debts'!$B$10:$B$19,S$6)) | Y6: =MATCH(4,'My Debts'!$K$10:$K$19,0) | Z6: =N(INDEX('My Debts'!$D$10:$D$19,Y$6))/100 | AA6: =IF(INDEX('My Debts'!$B$10:$B$19,Y$6)="",0,N(INDEX('My Debts'!$E$10:$E$19,Y$6))) | AB6: =IF(INDEX('My Debts'!$B$10:$B$19,Y$6)="",0,N(INDEX('My Debts'!$C$10:$C$19,Y$6))) | AC6: =IF(INDEX('My Debts'!$B$10:$B$19,Y$6)="","",INDEX('My Debts'!$B$10:$B$19,Y$6)) | AE6: =MATCH(5,'My Debts'!$K$10:$K$19,0) | AF6: =N(INDEX('My Debts'!$D$10:$D$19,AE$6))/100 | AG6: =IF(INDEX('My Debts'!$B$10:$B$19,AE$6)="",0,N(INDEX('My Debts'!$E$10:$E$19,AE$6))) | AH6: =IF(INDEX('My Debts'!$B$10:$B$19,AE$6)="",0,N(INDEX('My Debts'!$C$10:$C$19,AE$6))) | AI6: =IF(INDEX('My Debts'!$B$10:$B$19,AE$6)="","",INDEX('My Debts'!$B$10:$B$19,AE$6)) | AK6: =MATCH(6,'My Debts'!$K$10:$K$19,0) | AL6: =N(INDEX('My Debts'!$D$10:$D$19,AK$6))/100 | AM6: =IF(INDEX('My Debts'!$B$10:$B$19,AK$6)="",0,N(INDEX('My Debts'!$E$10:$E$19,AK$6))) | AN6: =IF(INDEX('My Debts'!$B$10:$B$19,AK$6)="",0,N(INDEX('My Debts'!$C$10:$C$19,AK$6))) | AO6: =IF(INDEX('My Debts'!$B$10:$B$19,AK$6)="","",INDEX('My Debts'!$B$10:$B$19,AK$6)) | AQ6: =MATCH(7,'My Debts'!$K$10:$K$19,0) | AR6: =N(INDEX('My Debts'!$D$10:$D$19,AQ$6))/100 | AS6: =IF(INDEX('My Debts'!$B$10:$B$19,AQ$6)="",0,N(INDEX('My Debts'!$E$10:$E$19,AQ$6))) | AT6: =IF(INDEX('My Debts'!$B$10:$B$19,AQ$6)="",0,N(INDEX('My Debts'!$C$10:$C$19,AQ$6))) | AU6: =IF(INDEX('My Debts'!$B$10:$B$19,AQ$6)="","",INDEX('My Debts'!$B$10:$B$19,AQ$6)) | AW6: =MATCH(8,'My Debts'!$K$10:$K$19,0) | AX6: =N(INDEX('My Debts'!$D$10:$D$19,AW$6))/100 | AY6: =IF(INDEX('My Debts'!$B$10:$B$19,AW$6)="",0,N(INDEX('My Debts'!$E$10:$E$19,AW$6))) | AZ6: =IF(INDEX('My Debts'!$B$10:$B$19,AW$6)="",0,N(INDEX('My Debts'!$C$10:$C$19,AW$6))) | BA6: =IF(INDEX('My Debts'!$B$10:$B$19,AW$6)="","",INDEX('My Debts'!$B$10:$B$19,AW$6)) | BC6: =MATCH(9,'My Debts'!$K$10:$K$19,0) | BD6: =N(INDEX('My Debts'!$D$10:$D$19,BC$6))/100 | BE6: =IF(INDEX('My Debts'!$B$10:$B$19,BC$6)="",0,N(INDEX('My Debts'!$E$10:$E$19,BC$6))) | BF6: =IF(INDEX('My Debts'!$B$10:$B$19,BC$6)="",0,N(INDEX('My Debts'!$C$10:$C$19,BC$6))) | BG6: =IF(INDEX('My Debts'!$B$10:$B$19,BC$6)="","",INDEX('My Debts'!$B$10:$B$19,BC$6)) | BI6: =MATCH(10,'My Debts'!$K$10:$K$19,0) | BJ6: =N(INDEX('My Debts'!$D$10:$D$19,BI$6))/100 | BK6: =IF(INDEX('My Debts'!$B$10:$B$19,BI$6)="",0,N(INDEX('My Debts'!$E$10:$E$19,BI$6))) | BL6: =IF(INDEX('My Debts'!$B$10:$B$19,BI$6)="",0,N(INDEX('My Debts'!$C$10:$C$19,BI$6))) | BM6: =IF(INDEX('My Debts'!$B$10:$B$19,BI$6)="","",INDEX('My Debts'!$B$10:$B$19,BI$6))
A7: Month | B7: Date | C7: Total owed (end) | D7: Paid this month | E7: Interest this month | G7: Start balance | H7: Interest | I7: Minimum paid | J7: Extra paid | K7: End balance | M7: Start balance | N7: Interest | O7: Minimum paid | P7: Extra paid | Q7: End balance | S7: Start balance | T7: Interest | U7: Minimum paid | V7: Extra paid | W7: End balance | Y7: Start balance | Z7: Interest | AA7: Minimum paid | AB7: Extra paid | AC7: End balance | AE7: Start balance | AF7: Interest | AG7: Minimum paid | AH7: Extra paid | AI7: End balance | AK7: Start balance | AL7: Interest | AM7: Minimum paid | AN7: Extra paid | AO7: End balance | AQ7: Start balance | AR7: Interest | AS7: Minimum paid | AT7: Extra paid | AU7: End balance | AW7: Start balance | AX7: Interest | AY7: Minimum paid | AZ7: Extra paid | BA7: End balance | BC7: Start balance | BD7: Interest | BE7: Minimum paid | BF7: Extra paid | BG7: End balance | BI7: Start balance | BJ7: Interest | BK7: Minimum paid | BL7: Extra paid | BM7: End balance
A8: 1 | B8: =EDATE('My Debts'!$C$6,A8-1) | C8: =K8+Q8+W8+AC8+AI8+AO8+AU8+BA8+BG8+BM8 | D8: =I8+O8+U8+AA8+AG8+AM8+AS8+AY8+BE8+BK8+J8+P8+V8+AB8+AH8+AN8+AT8+AZ8+BF8+BL8 | E8: =H8+N8+T8+Z8+AF8+AL8+AR8+AX8+BD8+BJ8 | F8: =MAX(0,'My Debts'!$E$21-(I8+O8+U8+AA8+AG8+AM8+AS8+AY8+BE8+BK8)) | G8: =J$6 | H8: =ROUND(G8*H$6/12,2) | I8: =MIN(I$6,G8+H8) | J8: =MAX(0,MIN(G8+H8-I8,$F8)) | K8: =ROUND(G8+H8-I8-J8,2) | L8: =$F8-J8 | M8: =P$6 | N8: =ROUND(M8*N$6/12,2) | O8: =MIN(O$6,M8+N8) | P8: =MAX(0,MIN(M8+N8-O8,L8)) | Q8: =ROUND(M8+N8-O8-P8,2) | R8: =L8-P8 | S8: =V$6 | T8: =ROUND(S8*T$6/12,2) | U8: =MIN(U$6,S8+T8) | V8: =MAX(0,MIN(S8+T8-U8,R8)) | W8: =ROUND(S8+T8-U8-V8,2) | X8: =R8-V8 | Y8: =AB$6 | Z8: =ROUND(Y8*Z$6/12,2) | AA8: =MIN(AA$6,Y8+Z8) | AB8: =MAX(0,MIN(Y8+Z8-AA8,X8)) | AC8: =ROUND(Y8+Z8-AA8-AB8,2) | AD8: =X8-AB8 | AE8: =AH$6 | AF8: =ROUND(AE8*AF$6/12,2) | AG8: =MIN(AG$6,AE8+AF8) | AH8: =MAX(0,MIN(AE8+AF8-AG8,AD8)) | AI8: =ROUND(AE8+AF8-AG8-AH8,2) | AJ8: =AD8-AH8 | AK8: =AN$6 | AL8: =ROUND(AK8*AL$6/12,2) | AM8: =MIN(AM$6,AK8+AL8) | AN8: =MAX(0,MIN(AK8+AL8-AM8,AJ8)) | AO8: =ROUND(AK8+AL8-AM8-AN8,2) | AP8: =AJ8-AN8 | AQ8: =AT$6 | AR8: =ROUND(AQ8*AR$6/12,2) | AS8: =MIN(AS$6,AQ8+AR8) | AT8: =MAX(0,MIN(AQ8+AR8-AS8,AP8)) | AU8: =ROUND(AQ8+AR8-AS8-AT8,2) | AV8: =AP8-AT8 | AW8: =AZ$6 | AX8: =ROUND(AW8*AX$6/12,2) | AY8: =MIN(AY$6,AW8+AX8) | AZ8: =MAX(0,MIN(AW8+AX8-AY8,AV8)) | BA8: =ROUND(AW8+AX8-AY8-AZ8,2) | BB8: =AV8-AZ8 | BC8: =BF$6 | BD8: =ROUND(BC8*BD$6/12,2) | BE8: =MIN(BE$6,BC8+BD8) | BF8: =MAX(0,MIN(BC8+BD8-BE8,BB8)) | BG8: =ROUND(BC8+BD8-BE8-BF8,2) | BH8: =BB8-BF8 | BI8: =BL$6 | BJ8: =ROUND(BI8*BJ$6/12,2) | BK8: =MIN(BK$6,BI8+BJ8) | BL8: =MAX(0,MIN(BI8+BJ8-BK8,BH8)) | BM8: =ROUND(BI8+BJ8-BK8-BL8,2) | BN8: =BH8-BL8
A9: 2 | B9: =EDATE('My Debts'!$C$6,A9-1) | C9: =K9+Q9+W9+AC9+AI9+AO9+AU9+BA9+BG9+BM9 | D9: =I9+O9+U9+AA9+AG9+AM9+AS9+AY9+BE9+BK9+J9+P9+V9+AB9+AH9+AN9+AT9+AZ9+BF9+BL9 | E9: =H9+N9+T9+Z9+AF9+AL9+AR9+AX9+BD9+BJ9 | F9: =MAX(0,'My Debts'!$E$21-(I9+O9+U9+AA9+AG9+AM9+AS9+AY9+BE9+BK9)) | G9: =K8 | H9: =ROUND(G9*H$6/12,2) | I9: =MIN(I$6,G9+H9) | J9: =MAX(0,MIN(G9+H9-I9,$F9)) | K9: =ROUND(G9+H9-I9-J9,2) | L9: =$F9-J9 | M9: =Q8 | N9: =ROUND(M9*N$6/12,2) | O9: =MIN(O$6,M9+N9) | P9: =MAX(0,MIN(M9+N9-O9,L9)) | Q9: =ROUND(M9+N9-O9-P9,2) | R9: =L9-P9 | S9: =W8 | T9: =ROUND(S9*T$6/12,2) | U9: =MIN(U$6,S9+T9) | V9: =MAX(0,MIN(S9+T9-U9,R9)) | W9: =ROUND(S9+T9-U9-V9,2) | X9: =R9-V9 | Y9: =AC8 | Z9: =ROUND(Y9*Z$6/12,2) | AA9: =MIN(AA$6,Y9+Z9) | AB9: =MAX(0,MIN(Y9+Z9-AA9,X9)) | AC9: =ROUND(Y9+Z9-AA9-AB9,2) | AD9: =X9-AB9 | AE9: =AI8 | AF9: =ROUND(AE9*AF$6/12,2) | AG9: =MIN(AG$6,AE9+AF9) | AH9: =MAX(0,MIN(AE9+AF9-AG9,AD9)) | AI9: =ROUND(AE9+AF9-AG9-AH9,2) | AJ9: =AD9-AH9 | AK9: =AO8 | AL9: =ROUND(AK9*AL$6/12,2) | AM9: =MIN(AM$6,AK9+AL9) | AN9: =MAX(0,MIN(AK9+AL9-AM9,AJ9)) | AO9: =ROUND(AK9+AL9-AM9-AN9,2) | AP9: =AJ9-AN9 | AQ9: =AU8 | AR9: =ROUND(AQ9*AR$6/12,2) | AS9: =MIN(AS$6,AQ9+AR9) | AT9: =MAX(0,MIN(AQ9+AR9-AS9,AP9)) | AU9: =ROUND(AQ9+AR9-AS9-AT9,2) | AV9: =AP9-AT9 | AW9: =BA8 | AX9: =ROUND(AW9*AX$6/12,2) | AY9: =MIN(AY$6,AW9+AX9) | AZ9: =MAX(0,MIN(AW9+AX9-AY9,AV9)) | BA9: =ROUND(AW9+AX9-AY9-AZ9,2) | BB9: =AV9-AZ9 | BC9: =BG8 | BD9: =ROUND(BC9*BD$6/12,2) | BE9: =MIN(BE$6,BC9+BD9) | BF9: =MAX(0,MIN(BC9+BD9-BE9,BB9)) | BG9: =ROUND(BC9+BD9-BE9-BF9,2) | BH9: =BB9-BF9 | BI9: =BM8 | BJ9: =ROUND(BI9*BJ$6/12,2) | BK9: =MIN(BK$6,BI9+BJ9) | BL9: =MAX(0,MIN(BI9+BJ9-BK9,BH9)) | BM9: =ROUND(BI9+BJ9-BK9-BL9,2) | BN9: =BH9-BL9
A10: 3 | B10: =EDATE('My Debts'!$C$6,A10-1) | C10: =K10+Q10+W10+AC10+AI10+AO10+AU10+BA10+BG10+BM10 | D10: =I10+O10+U10+AA10+AG10+AM10+AS10+AY10+BE10+BK10+J10+P10+V10+AB10+AH10+AN10+AT10+AZ10+BF10+BL10 | E10: =H10+N10+T10+Z10+AF10+AL10+AR10+AX10+BD10+BJ10 | F10: =MAX(0,'My Debts'!$E$21-(I10+O10+U10+AA10+AG10+AM10+AS10+AY10+BE10+BK10)) | G10: =K9 | H10: =ROUND(G10*H$6/12,2) | I10: =MIN(I$6,G10+H10) | J10: =MAX(0,MIN(G10+H10-I10,$F10)) | K10: =ROUND(G10+H10-I10-J10,2) | L10: =$F10-J10 | M10: =Q9 | N10: =ROUND(M10*N$6/12,2) | O10: =MIN(O$6,M10+N10) | P10: =MAX(0,MIN(M10+N10-O10,L10)) | Q10: =ROUND(M10+N10-O10-P10,2) | R10: =L10-P10 | S10: =W9 | T10: =ROUND(S10*T$6/12,2) | U10: =MIN(U$6,S10+T10) | V10: =MAX(0,MIN(S10+T10-U10,R10)) | W10: =ROUND(S10+T10-U10-V10,2) | X10: =R10-V10 | Y10: =AC9 | Z10: =ROUND(Y10*Z$6/12,2) | AA10: =MIN(AA$6,Y10+Z10) | AB10: =MAX(0,MIN(Y10+Z10-AA10,X10)) | AC10: =ROUND(Y10+Z10-AA10-AB10,2) | AD10: =X10-AB10 | AE10: =AI9 | AF10: =ROUND(AE10*AF$6/12,2) | AG10: =MIN(AG$6,AE10+AF10) | AH10: =MAX(0,MIN(AE10+AF10-AG10,AD10)) | AI10: =ROUND(AE10+AF10-AG10-AH10,2) | AJ10: =AD10-AH10 | AK10: =AO9 | AL10: =ROUND(AK10*AL$6/12,2) | AM10: =MIN(AM$6,AK10+AL10) | AN10: =MAX(0,MIN(AK10+AL10-AM10,AJ10)) | AO10: =ROUND(AK10+AL10-AM10-AN10,2) | AP10: =AJ10-AN10 | AQ10: =AU9 | AR10: =ROUND(AQ10*AR$6/12,2) | AS10: =MIN(AS$6,AQ10+AR10) | AT10: =MAX(0,MIN(AQ10+AR10-AS10,AP10)) | AU10: =ROUND(AQ10+AR10-AS10-AT10,2) | AV10: =AP10-AT10 | AW10: =BA9 | AX10: =ROUND(AW10*AX$6/12,2) | AY10: =MIN(AY$6,AW10+AX10) | AZ10: =MAX(0,MIN(AW10+AX10-AY10,AV10)) | BA10: =ROUND(AW10+AX10-AY10-AZ10,2) | BB10: =AV10-AZ10 | BC10: =BG9 | BD10: =ROUND(BC10*BD$6/12,2) | BE10: =MIN(BE$6,BC10+BD10) | BF10: =MAX(0,MIN(BC10+BD10-BE10,BB10)) | BG10: =ROUND(BC10+BD10-BE10-BF10,2) | BH10: =BB10-BF10 | BI10: =BM9 | BJ10: =ROUND(BI10*BJ$6/12,2) | BK10: =MIN(BK$6,BI10+BJ10) | BL10: =MAX(0,MIN(BI10+BJ10-BK10,BH10)) | BM10: =ROUND(BI10+BJ10-BK10-BL10,2) | BN10: =BH10-BL10
A11: 4 | B11: =EDATE('My Debts'!$C$6,A11-1) | C11: =K11+Q11+W11+AC11+AI11+AO11+AU11+BA11+BG11+BM11 | D11: =I11+O11+U11+AA11+AG11+AM11+AS11+AY11+BE11+BK11+J11+P11+V11+AB11+AH11+AN11+AT11+AZ11+BF11+BL11 | E11: =H11+N11+T11+Z11+AF11+AL11+AR11+AX11+BD11+BJ11 | F11: =MAX(0,'My Debts'!$E$21-(I11+O11+U11+AA11+AG11+AM11+AS11+AY11+BE11+BK11)) | G11: =K10 | H11: =ROUND(G11*H$6/12,2) | I11: =MIN(I$6,G11+H11) | J11: =MAX(0,MIN(G11+H11-I11,$F11)) | K11: =ROUND(G11+H11-I11-J11,2) | L11: =$F11-J11 | M11: =Q10 | N11: =ROUND(M11*N$6/12,2) | O11: =MIN(O$6,M11+N11) | P11: =MAX(0,MIN(M11+N11-O11,L11)) | Q11: =ROUND(M11+N11-O11-P11,2) | R11: =L11-P11 | S11: =W10 | T11: =ROUND(S11*T$6/12,2) | U11: =MIN(U$6,S11+T11) | V11: =MAX(0,MIN(S11+T11-U11,R11)) | W11: =ROUND(S11+T11-U11-V11,2) | X11: =R11-V11 | Y11: =AC10 | Z11: =ROUND(Y11*Z$6/12,2) | AA11: =MIN(AA$6,Y11+Z11) | AB11: =MAX(0,MIN(Y11+Z11-AA11,X11)) | AC11: =ROUND(Y11+Z11-AA11-AB11,2) | AD11: =X11-AB11 | AE11: =AI10 | AF11: =ROUND(AE11*AF$6/12,2) | AG11: =MIN(AG$6,AE11+AF11) | AH11: =MAX(0,MIN(AE11+AF11-AG11,AD11)) | AI11: =ROUND(AE11+AF11-AG11-AH11,2) | AJ11: =AD11-AH11 | AK11: =AO10 | AL11: =ROUND(AK11*AL$6/12,2) | AM11: =MIN(AM$6,AK11+AL11) | AN11: =MAX(0,MIN(AK11+AL11-AM11,AJ11)) | AO11: =ROUND(AK11+AL11-AM11-AN11,2) | AP11: =AJ11-AN11 | AQ11: =AU10 | AR11: =ROUND(AQ11*AR$6/12,2) | AS11: =MIN(AS$6,AQ11+AR11) | AT11: =MAX(0,MIN(AQ11+AR11-AS11,AP11)) | AU11: =ROUND(AQ11+AR11-AS11-AT11,2) | AV11: =AP11-AT11 | AW11: =BA10 | AX11: =ROUND(AW11*AX$6/12,2) | AY11: =MIN(AY$6,AW11+AX11) | AZ11: =MAX(0,MIN(AW11+AX11-AY11,AV11)) | BA11: =ROUND(AW11+AX11-AY11-AZ11,2) | BB11: =AV11-AZ11 | BC11: =BG10 | BD11: =ROUND(BC11*BD$6/12,2) | BE11: =MIN(BE$6,BC11+BD11) | BF11: =MAX(0,MIN(BC11+BD11-BE11,BB11)) | BG11: =ROUND(BC11+BD11-BE11-BF11,2) | BH11: =BB11-BF11 | BI11: =BM10 | BJ11: =ROUND(BI11*BJ$6/12,2) | BK11: =MIN(BK$6,BI11+BJ11) | BL11: =MAX(0,MIN(BI11+BJ11-BK11,BH11)) | BM11: =ROUND(BI11+BJ11-BK11-BL11,2) | BN11: =BH11-BL11
A12: 5 | B12: =EDATE('My Debts'!$C$6,A12-1) | C12: =K12+Q12+W12+AC12+AI12+AO12+AU12+BA12+BG12+BM12 | D12: =I12+O12+U12+AA12+AG12+AM12+AS12+AY12+BE12+BK12+J12+P12+V12+AB12+AH12+AN12+AT12+AZ12+BF12+BL12 | E12: =H12+N12+T12+Z12+AF12+AL12+AR12+AX12+BD12+BJ12 | F12: =MAX(0,'My Debts'!$E$21-(I12+O12+U12+AA12+AG12+AM12+AS12+AY12+BE12+BK12)) | G12: =K11 | H12: =ROUND(G12*H$6/12,2) | I12: =MIN(I$6,G12+H12) | J12: =MAX(0,MIN(G12+H12-I12,$F12)) | K12: =ROUND(G12+H12-I12-J12,2) | L12: =$F12-J12 | M12: =Q11 | N12: =ROUND(M12*N$6/12,2) | O12: =MIN(O$6,M12+N12) | P12: =MAX(0,MIN(M12+N12-O12,L12)) | Q12: =ROUND(M12+N12-O12-P12,2) | R12: =L12-P12 | S12: =W11 | T12: =ROUND(S12*T$6/12,2) | U12: =MIN(U$6,S12+T12) | V12: =MAX(0,MIN(S12+T12-U12,R12)) | W12: =ROUND(S12+T12-U12-V12,2) | X12: =R12-V12 | Y12: =AC11 | Z12: =ROUND(Y12*Z$6/12,2) | AA12: =MIN(AA$6,Y12+Z12) | AB12: =MAX(0,MIN(Y12+Z12-AA12,X12)) | AC12: =ROUND(Y12+Z12-AA12-AB12,2) | AD12: =X12-AB12 | AE12: =AI11 | AF12: =ROUND(AE12*AF$6/12,2) | AG12: =MIN(AG$6,AE12+AF12) | AH12: =MAX(0,MIN(AE12+AF12-AG12,AD12)) | AI12: =ROUND(AE12+AF12-AG12-AH12,2) | AJ12: =AD12-AH12 | AK12: =AO11 | AL12: =ROUND(AK12*AL$6/12,2) | AM12: =MIN(AM$6,AK12+AL12) | AN12: =MAX(0,MIN(AK12+AL12-AM12,AJ12)) | AO12: =ROUND(AK12+AL12-AM12-AN12,2) | AP12: =AJ12-AN12 | AQ12: =AU11 | AR12: =ROUND(AQ12*AR$6/12,2) | AS12: =MIN(AS$6,AQ12+AR12) | AT12: =MAX(0,MIN(AQ12+AR12-AS12,AP12)) | AU12: =ROUND(AQ12+AR12-AS12-AT12,2) | AV12: =AP12-AT12 | AW12: =BA11 | AX12: =ROUND(AW12*AX$6/12,2) | AY12: =MIN(AY$6,AW12+AX12) | AZ12: =MAX(0,MIN(AW12+AX12-AY12,AV12)) | BA12: =ROUND(AW12+AX12-AY12-AZ12,2) | BB12: =AV12-AZ12 | BC12: =BG11 | BD12: =ROUND(BC12*BD$6/12,2) | BE12: =MIN(BE$6,BC12+BD12) | BF12: =MAX(0,MIN(BC12+BD12-BE12,BB12)) | BG12: =ROUND(BC12+BD12-BE12-BF12,2) | BH12: =BB12-BF12 | BI12: =BM11 | BJ12: =ROUND(BI12*BJ$6/12,2) | BK12: =MIN(BK$6,BI12+BJ12) | BL12: =MAX(0,MIN(BI12+BJ12-BK12,BH12)) | BM12: =ROUND(BI12+BJ12-BK12-BL12,2) | BN12: =BH12-BL12
